Workbook

Sheet Presença
A1: Carimbo de data/hora | B1: Nome Completo: | C1: CPF: XXX.XXX.XXX-XX | D1: Telefone: (DD)XXXXX-XXXX | E1: E-mail: xxxxxxx@xxxmail.com | F1: inscrito | K1: Data de Nascimento | L1: Telefone (XX)XXXXX-XXXX | M1: Município que representa: | N1: Você faz parte do: | O1: Que cargo você ocupa na gestão municipal? | P1: Prezado(a) Gestor(a), Se existe algum caso de sucesso da gestão do transporte escolar no seu município, gostaríamos conhecer mais um pouco ao respeito. Por favor, relate de forma sucinta o caso de sucesso no espaço a seguir: | Q1: Que cargo você ocupa no CACS-FUNDEB?
A2: 45924.363 | B2: João Paulo de Sousa | C2: 011.848.541-57 | D2: (66)98432-9186 | E2: 999214662abc@gmail.com | F2: Sim | G2: =IF(_xlfn.XLOOKUP($C2,Incrições!$D$2:$D$58,Incrições!A$2:A$58)=0,"",_xlfn.XLOOKUP($C2,Incrições!$D$2:$D$58,Incrições!A$2:A$58)) -> 45912.518 | H2: =IF(_xlfn.XLOOKUP($C2,Incrições!$D$2:$D$58,Incrições!B$2:B$58)=0,"",_xlfn.XLOOKUP($C2,Incrições!$D$2:$D$58,Incrições!B$2:B$58)) -> 999214662abc@gmail.com | I2: =IF(_xlfn.XLOOKUP($C2,Incrições!$D$2:$D$58,Incrições!C$2:C$58)=0,"",_xlfn.XLOOKUP($C2,Incrições!$D$2:$D$58,Incrições!C$2:C$58)) -> João Paulo de Sousa | J2: =IF(_xlfn.XLOOKUP($C2,Incrições!$D$2:$D$58,Incrições!D$2:D$58)=0,"",_xlfn.XLOOKUP($C2,Incrições!$D$2:$D$58,Incrições!D$2:D$58)) -> 011.848.541-57 | K2: =IF(_xlfn.XLOOKUP($C2,Incrições!$D$2:$D$58,Incrições!E$2:E$58)=0,"",_xlfn.XLOOKUP($C2,Incrições!$D$2:$D$58,Incrições!E$2:E$58)) -> 29917 | L2: =IF(_xlfn.XLOOKUP($C2,Incrições!$D$2:$D$58,Incrições!F$2:F$58)=0,"",_xlfn.XLOOKUP($C2,Incrições!$D$2:$D$58,Incrições!F$2:F$58)) -> (66)98432-9186 | M2: =IF(_xlfn.XLOOKUP($C2,Incrições!$D$2:$D$58,Incrições!G$2:G$58)=0,"",_xlfn.XLOOKUP($C2,Incrições!$D$2:$D$58,Incrições!G$2:G$58)) -> Água Boa (MT) | N2: =IF(_xlfn.XLOOKUP($C2,Incrições!$D$2:$D$58,Incrições!H$2:H$58)=0,"",_xlfn.XLOOKUP($C2,Incrições!$D$2:$D$58,Incrições!H$2:H$58)) -> Gestão municipal | ... R2: =IF(_xlfn.XLOOKUP($C2,Incrições!$D$2:$D$58,Incrições!L$2:L$58)=0,"",_xlfn.XLOOKUP($C2,Incrições!$D$2:$D$58,Incrições!L$2:L$58)) -> 45924
A3: 45924.359 | B3: Gabriel Kasprczak da silva | C3: 935.418.991-15 | D3: (66)99982-2518 | E3: gabrielksilva@hotmail.com | F3: Sim | G3: =IF(_xlfn.XLOOKUP($C3,Incrições!$D$2:$D$58,Incrições!A$2:A$58)=0,"",_xlfn.XLOOKUP($C3,Incrições!$D$2:$D$58,Incrições!A$2:A$58)) -> 45905.597 | H3: =IF(_xlfn.XLOOKUP($C3,Incrições!$D$2:$D$58,Incrições!B$2:B$58)=0,"",_xlfn.XLOOKUP($C3,Incrições!$D$2:$D$58,Incrições!B$2:B$58)) -> admin.transporte@canarana.edu.mt.gov.br | I3: =IF(_xlfn.XLOOKUP($C3,Incrições!$D$2:$D$58,Incrições!C$2:C$58)=0,"",_xlfn.XLOOKUP($C3,Incrições!$D$2:$D$58,Incrições!C$2:C$58)) -> Gabriel Kasprczak da Silva | J3: =IF(_xlfn.XLOOKUP($C3,Incrições!$D$2:$D$58,Incrições!D$2:D$58)=0,"",_xlfn.XLOOKUP($C3,Incrições!$D$2:$D$58,Incrições!D$2:D$58)) -> 935.418.991-15 | K3: =IF(_xlfn.XLOOKUP($C3,Incrições!$D$2:$D$58,Incrições!E$2:E$58)=0,"",_xlfn.XLOOKUP($C3,Incrições!$D$2:$D$58,Incrições!E$2:E$58)) -> 30299 | L3: =IF(_xlfn.XLOOKUP($C3,Incrições!$D$2:$D$58,Incrições!F$2:F$58)=0,"",_xlfn.XLOOKUP($C3,Incrições!$D$2:$D$58,Incrições!F$2:F$58)) -> (66)99982-2518 | M3: =IF(_xlfn.XLOOKUP($C3,Incrições!$D$2:$D$58,Incrições!G$2:G$58)=0,"",_xlfn.XLOOKUP($C3,Incrições!$D$2:$D$58,Incrições!G$2:G$58)) -> Canarana (MT) | N3: =IF(_xlfn.XLOOKUP($C3,Incrições!$D$2:$D$58,Incrições!H$2:H$58)=0,"",_xlfn.XLOOKUP($C3,Incrições!$D$2:$D$58,Incrições!H$2:H$58)) -> Gestão municipal | ... R3: =IF(_xlfn.XLOOKUP($C3,Incrições!$D$2:$D$58,Incrições!L$2:L$58)=0,"",_xlfn.XLOOKUP($C3,Incrições!$D$2:$D$58,Incrições!L$2:L$58)) -> 45924
A4: 45924.366 | B4: Rosirene Alves Martins Aguiar | C4: 921.708.031-49 | D4: (66)98147-1011 | E4: aguiarrosirene8@gmail.com | F4: Sim | G4: =IF(_xlfn.XLOOKUP($C4,Incrições!$D$2:$D$58,Incrições!A$2:A$58)=0,"",_xlfn.XLOOKUP($C4,Incrições!$D$2:$D$58,Incrições!A$2:A$58)) -> 45910.412 | H4: =IF(_xlfn.XLOOKUP($C4,Incrições!$D$2:$D$58,Incrições!B$2:B$58)=0,"",_xlfn.XLOOKUP($C4,Incrições!$D$2:$D$58,Incrições!B$2:B$58)) -> aguiarrosirene8@gmail.com | I4: =IF(_xlfn.XLOOKUP($C4,Incrições!$D$2:$D$58,Incrições!C$2:C$58)=0,"",_xlfn.XLOOKUP($C4,Incrições!$D$2:$D$58,Incrições!C$2:C$58)) -> Rosirene Alves Martins Aguiar | J4: =IF(_xlfn.XLOOKUP($C4,Incrições!$D$2:$D$58,Incrições!D$2:D$58)=0,"",_xlfn.XLOOKUP($C4,Incrições!$D$2:$D$58,Incrições!D$2:D$58)) -> 921.708.031-49 | K4: =IF(_xlfn.XLOOKUP($C4,Incrições!$D$2:$D$58,Incrições!E$2:E$58)=0,"",_xlfn.XLOOKUP($C4,Incrições!$D$2:$D$58,Incrições!E$2:E$58)) -> 27490 | L4: =IF(_xlfn.XLOOKUP($C4,Incrições!$D$2:$D$58,Incrições!F$2:F$58)=0,"",_xlfn.XLOOKUP($C4,Incrições!$D$2:$D$58,Incrições!F$2:F$58)) -> (66)98147-1011 | M4: =IF(_xlfn.XLOOKUP($C4,Incrições!$D$2:$D$58,Incrições!G$2:G$58)=0,"",_xlfn.XLOOKUP($C4,Incrições!$D$2:$D$58,Incrições!G$2:G$58)) -> Novo São Joaquim (MT) | N4: =IF(_xlfn.XLOOKUP($C4,Incrições!$D$2:$D$58,Incrições!H$2:H$58)=0,"",_xlfn.XLOOKUP($C4,Incrições!$D$2:$D$58,Incrições!H$2:H$58)) -> Gestão municipal | ... R4: =IF(_xlfn.XLOOKUP($C4,Incrições!$D$2:$D$58,Incrições!L$2:L$58)=0,"",_xlfn.XLOOKUP($C4,Incrições!$D$2:$D$58,Incrições!L$2:L$58)) -> 45924
A5: 45924.357 | B5: Cristian Alex Lopes de Souza | C5: 555.206.261-20 | D5: (66)99975-7560 | E5: alexcristian2312@gmail.com | F5: Sim | G5: =IF(_xlfn.XLOOKUP($C5,Incrições!$D$2:$D$58,Incrições!A$2:A$58)=0,"",_xlfn.XLOOKUP($C5,Incrições!$D$2:$D$58,Incrições!A$2:A$58)) -> 45909.446 | H5: =IF(_xlfn.XLOOKUP($C5,Incrições!$D$2:$D$58,Incrições!B$2:B$58)=0,"",_xlfn.XLOOKUP($C5,Incrições!$D$2:$D$58,Incrições!B$2:B$58)) -> alexcristian2312@gmail.com | I5: =IF(_xlfn.XLOOKUP($C5,Incrições!$D$2:$D$58,Incrições!C$2:C$58)=0,"",_xlfn.XLOOKUP($C5,Incrições!$D$2:$D$58,Incrições!C$2:C$58)) -> Cristian Alex Lopes de Souza | J5: =IF(_xlfn.XLOOKUP($C5,Incrições!$D$2:$D$58,Incrições!D$2:D$58)=0,"",_xlfn.XLOOKUP($C5,Incrições!$D$2:$D$58,Incrições!D$2:D$58)) -> 555.206.261-20 | K5: =IF(_xlfn.XLOOKUP($C5,Incrições!$D$2:$D$58,Incrições!E$2:E$58)=0,"",_xlfn.XLOOKUP($C5,Incrições!$D$2:$D$58,Incrições!E$2:E$58)) -> 27408 | L5: =IF(_xlfn.XLOOKUP($C5,Incrições!$D$2:$D$58,Incrições!F$2:F$58)=0,"",_xlfn.XLOOKUP($C5,Incrições!$D$2:$D$58,Incrições!F$2:F$58)) -> (66)99975-7560 | M5: =IF(_xlfn.XLOOKUP($C5,Incrições!$D$2:$D$58,Incrições!G$2:G$58)=0,"",_xlfn.XLOOKUP($C5,Incrições!$D$2:$D$58,Incrições!G$2:G$58)) -> Confresa (MT) | N5: =IF(_xlfn.XLOOKUP($C5,Incrições!$D$2:$D$58,Incrições!H$2:H$58)=0,"",_xlfn.XLOOKUP($C5,Incrições!$D$2:$D$58,Incrições!H$2:H$58)) -> CACS-FUNDEB | ... R5: =IF(_xlfn.XLOOKUP($C5,Incrições!$D$2:$D$58,Incrições!L$2:L$58)=0,"",_xlfn.XLOOKUP($C5,Incrições!$D$2:$D$58,Incrições!L$2:L$58)) -> 45924
A6: 45925.36 | B6: Andreia Arruda Américo | C6: 009.151.451-70 | D6: (66)98426-3841 | E6: americoandreia48@gmail.com | F6: Não | G6: =IF(_xlfn.XLOOKUP($C6,Incrições!$D$2:$D$58,Incrições!A$2:A$58)=0,"",_xlfn.XLOOKUP($C6,Incrições!$D$2:$D$58,Incrições!A$2:A$58)) -> 45908.479 | H6: =IF(_xlfn.XLOOKUP($C6,Incrições!$D$2:$D$58,Incrições!B$2:B$58)=0,"",_xlfn.XLOOKUP($C6,Incrições!$D$2:$D$58,Incrições!B$2:B$58)) -> americoandreia48@gmail.com | I6: =IF(_xlfn.XLOOKUP($C6,Incrições!$D$2:$D$58,Incrições!C$2:C$58)=0,"",_xlfn.XLOOKUP($C6,Incrições!$D$2:$D$58,Incrições!C$2:C$58)) -> Andreia Arruda Américo | J6: =IF(_xlfn.XLOOKUP($C6,Incrições!$D$2:$D$58,Incrições!D$2:D$58)=0,"",_xlfn.XLOOKUP($C6,Incrições!$D$2:$D$58,Incrições!D$2:D$58)) -> 009.151.451-70 | K6: =IF(_xlfn.XLOOKUP($C6,Incrições!$D$2:$D$58,Incrições!E$2:E$58)=0,"",_xlfn.XLOOKUP($C6,Incrições!$D$2:$D$58,Incrições!E$2:E$58)) -> 30150 | L6: =IF(_xlfn.XLOOKUP($C6,Incrições!$D$2:$D$58,Incrições!F$2:F$58)=0,"",_xlfn.XLOOKUP($C6,Incrições!$D$2:$D$58,Incrições!F$2:F$58)) -> (66)98426-3841 | M6: =IF(_xlfn.XLOOKUP($C6,Incrições!$D$2:$D$58,Incrições!G$2:G$58)=0,"",_xlfn.XLOOKUP($C6,Incrições!$D$2:$D$58,Incrições!G$2:G$58)) -> São Félix do Araguaia (MT) | N6: =IF(_xlfn.XLOOKUP($C6,Incrições!$D$2:$D$58,Incrições!H$2:H$58)=0,"",_xlfn.XLOOKUP($C6,Incrições!$D$2:$D$58,Incrições!H$2:H$58)) -> Gestão municipal | ... R6: =IF(_xlfn.XLOOKUP($C6,Incrições!$D$2:$D$58,Incrições!L$2:L$58)=0,"",_xlfn.XLOOKUP($C6,Incrições!$D$2:$D$58,Incrições!L$2:L$58)) -> 45925
A7: 45925.349 | B7: Andréa Paciente Hora | C7: 013.540.821-09 | D7: (66)98425-6888 | E7: andrea_hora21@hotmail.com | F7: Sim | G7: =IF(_xlfn.XLOOKUP($C7,Incrições!$D$2:$D$58,Incrições!A$2:A$58)=0,"",_xlfn.XLOOKUP($C7,Incrições!$D$2:$D$58,Incrições!A$2:A$58)) -> 45922.39 | H7: =IF(_xlfn.XLOOKUP($C7,Incrições!$D$2:$D$58,Incrições!B$2:B$58)=0,"",_xlfn.XLOOKUP($C7,Incrições!$D$2:$D$58,Incrições!B$2:B$58)) -> andrea_hora21@hotmail.com | I7: =IF(_xlfn.XLOOKUP($C7,Incrições!$D$2:$D$58,Incrições!C$2:C$58)=0,"",_xlfn.XLOOKUP($C7,Incrições!$D$2:$D$58,Incrições!C$2:C$58)) -> Andrea Paciente Hora | J7: =IF(_xlfn.XLOOKUP($C7,Incrições!$D$2:$D$58,Incrições!D$2:D$58)=0,"",_xlfn.XLOOKUP($C7,Incrições!$D$2:$D$58,Incrições!D$2:D$58)) -> 013.540.821-09 | K7: =IF(_xlfn.XLOOKUP($C7,Incrições!$D$2:$D$58,Incrições!E$2:E$58)=0,"",_xlfn.XLOOKUP($C7,Incrições!$D$2:$D$58,Incrições!E$2:E$58)) -> 31739 | L7: =IF(_xlfn.XLOOKUP($C7,Incrições!$D$2:$D$58,Incrições!F$2:F$58)=0,"",_xlfn.XLOOKUP($C7,Incrições!$D$2:$D$58,Incrições!F$2:F$58)) -> (66)98425-6888 | M7: =IF(_xlfn.XLOOKUP($C7,Incrições!$D$2:$D$58,Incrições!G$2:G$58)=0,"",_xlfn.XLOOKUP($C7,Incrições!$D$2:$D$58,Incrições!G$2:G$58)) -> Vila Rica (MT) | N7: =IF(_xlfn.XLOOKUP($C7,Incrições!$D$2:$D$58,Incrições!H$2:H$58)=0,"",_xlfn.XLOOKUP($C7,Incrições!$D$2:$D$58,Incrições!H$2:H$58)) -> CACS-FUNDEB | ... R7: =IF(_xlfn.XLOOKUP($C7,Incrições!$D$2:$D$58,Incrições!L$2:L$58)=0,"",_xlfn.XLOOKUP($C7,Incrições!$D$2:$D$58,Incrições!L$2:L$58)) -> 45925
A8: 45925.417 | B8: CAIQUE MATHEUS DA SILVA | C8: 055.960.981-75 | D8: (66)98446-6322 | E8: caiquematheussnd1@gmail.com | F8: Sim | G8: =IF(_xlfn.XLOOKUP($C8,Incrições!$D$2:$D$58,Incrições!A$2:A$58)=0,"",_xlfn.XLOOKUP($C8,Incrições!$D$2:$D$58,Incrições!A$2:A$58)) -> 45917.364 | H8: =IF(_xlfn.XLOOKUP($C8,Incrições!$D$2:$D$58,Incrições!B$2:B$58)=0,"",_xlfn.XLOOKUP($C8,Incrições!$D$2:$D$58,Incrições!B$2:B$58)) -> caiquematheussnd1@gmail.com | I8: =IF(_xlfn.XLOOKUP($C8,Incrições!$D$2:$D$58,Incrições!C$2:C$58)=0,"",_xlfn.XLOOKUP($C8,Incrições!$D$2:$D$58,Incrições!C$2:C$58)) -> CAIQUE MATHEUS DA SILVA | J8: =IF(_xlfn.XLOOKUP($C8,Incrições!$D$2:$D$58,Incrições!D$2:D$58)=0,"",_xlfn.XLOOKUP($C8,Incrições!$D$2:$D$58,Incrições!D$2:D$58)) -> 055.960.981-75 | K8: =IF(_xlfn.XLOOKUP($C8,Incrições!$D$2:$D$58,Incrições!E$2:E$58)=0,"",_xlfn.XLOOKUP($C8,Incrições!$D$2:$D$58,Incrições!E$2:E$58)) -> 34279 | L8: =IF(_xlfn.XLOOKUP($C8,Incrições!$D$2:$D$58,Incrições!F$2:F$58)=0,"",_xlfn.XLOOKUP($C8,Incrições!$D$2:$D$58,Incrições!F$2:F$58)) -> (66)98446-6322 | M8: =IF(_xlfn.XLOOKUP($C8,Incrições!$D$2:$D$58,Incrições!G$2:G$58)=0,"",_xlfn.XLOOKUP($C8,Incrições!$D$2:$D$58,Incrições!G$2:G$58)) -> Serra Nova Dourada (MT) | N8: =IF(_xlfn.XLOOKUP($C8,Incrições!$D$2:$D$58,Incrições!H$2:H$58)=0,"",_xlfn.XLOOKUP($C8,Incrições!$D$2:$D$58,Incrições!H$2:H$58)) -> CACS-FUNDEB | ... R8: =IF(_xlfn.XLOOKUP($C8,Incrições!$D$2:$D$58,Incrições!L$2:L$58)=0,"",_xlfn.XLOOKUP($C8,Incrições!$D$2:$D$58,Incrições!L$2:L$58)) -> 45925
A9: 45924.359 | B9: Celson Sousa da Silva | C9: 951.230.831-20 | D9: (66)98445-7805 | E9: Celsonsousadasilva@hotmail.com | F9: Sim | G9: =IF(_xlfn.XLOOKUP($C9,Incrições!$D$2:$D$58,Incrições!A$2:A$58)=0,"",_xlfn.XLOOKUP($C9,Incrições!$D$2:$D$58,Incrições!A$2:A$58)) -> 45909.587 | H9: =IF(_xlfn.XLOOKUP($C9,Incrições!$D$2:$D$58,Incrições!B$2:B$58)=0,"",_xlfn.XLOOKUP($C9,Incrições!$D$2:$D$58,Incrições!B$2:B$58)) -> celsonsousadasilva@hotmail.com | I9: =IF(_xlfn.XLOOKUP($C9,Incrições!$D$2:$D$58,Incrições!C$2:C$58)=0,"",_xlfn.XLOOKUP($C9,Incrições!$D$2:$D$58,Incrições!C$2:C$58)) -> Celson Sousa da Silva | J9: =IF(_xlfn.XLOOKUP($C9,Incrições!$D$2:$D$58,Incrições!D$2:D$58)=0,"",_xlfn.XLOOKUP($C9,Incrições!$D$2:$D$58,Incrições!D$2:D$58)) -> 951.230.831-20 | K9: =IF(_xlfn.XLOOKUP($C9,Incrições!$D$2:$D$58,Incrições!E$2:E$58)=0,"",_xlfn.XLOOKUP($C9,Incrições!$D$2:$D$58,Incrições!E$2:E$58)) -> 29800 | L9: =IF(_xlfn.XLOOKUP($C9,Incrições!$D$2:$D$58,Incrições!F$2:F$58)=0,"",_xlfn.XLOOKUP($C9,Incrições!$D$2:$D$58,Incrições!F$2:F$58)) -> (66)98445-7805 | M9: =IF(_xlfn.XLOOKUP($C9,Incrições!$D$2:$D$58,Incrições!G$2:G$58)=0,"",_xlfn.XLOOKUP($C9,Incrições!$D$2:$D$58,Incrições!G$2:G$58)) -> Confresa (MT) | N9: =IF(_xlfn.XLOOKUP($C9,Incrições!$D$2:$D$58,Incrições!H$2:H$58)=0,"",_xlfn.XLOOKUP($C9,Incrições!$D$2:$D$58,Incrições!H$2:H$58)) -> CACS-FUNDEB | ... R9: =IF(_xlfn.XLOOKUP($C9,Incrições!$D$2:$D$58,Incrições!L$2:L$58)=0,"",_xlfn.XLOOKUP($C9,Incrições!$D$2:$D$58,Incrições!L$2:L$58)) -> 45924
A10: 45924.357 | B10: MARCIO UONDERSON RAIMUNDO | C10: 956.523.701-06 | D10: (66)99978-8010 | E10: cintiaraimundo70@gmail.com | F10: Sim | G10: =IF(_xlfn.XLOOKUP($C10,Incrições!$D$2:$D$58,Incrições!A$2:A$58)=0,"",_xlfn.XLOOKUP($C10,Incrições!$D$2:$D$58,Incrições!A$2:A$58)) -> 45905.593 | H10: =IF(_xlfn.XLOOKUP($C10,Incrições!$D$2:$D$58,Incrições!B$2:B$58)=0,"",_xlfn.XLOOKUP($C10,Incrições!$D$2:$D$58,Incrições!B$2:B$58)) -> cintiaraimundo70@gmail.com | I10: =IF(_xlfn.XLOOKUP($C10,Incrições!$D$2:$D$58,Incrições!C$2:C$58)=0,"",_xlfn.XLOOKUP($C10,Incrições!$D$2:$D$58,Incrições!C$2:C$58)) -> Cintia de Almeida Oliveira Raimundo | J10: =IF(_xlfn.XLOOKUP($C10,Incrições!$D$2:$D$58,Incrições!D$2:D$58)=0,"",_xlfn.XLOOKUP($C10,Incrições!$D$2:$D$58,Incrições!D$2:D$58)) -> 956.523.701-06 | K10: =IF(_xlfn.XLOOKUP($C10,Incrições!$D$2:$D$58,Incrições!E$2:E$58)=0,"",_xlfn.XLOOKUP($C10,Incrições!$D$2:$D$58,Incrições!E$2:E$58)) -> 30047 | L10: =IF(_xlfn.XLOOKUP($C10,Incrições!$D$2:$D$58,Incrições!F$2:F$58)=0,"",_xlfn.XLOOKUP($C10,Incrições!$D$2:$D$58,Incrições!F$2:F$58)) -> (66)99978-8010 | M10: =IF(_xlfn.XLOOKUP($C10,Incrições!$D$2:$D$58,Incrições!G$2:G$58)=0,"",_xlfn.XLOOKUP($C10,Incrições!$D$2:$D$58,Incrições!G$2:G$58)) -> Canarana (MT) | N10: =IF(_xlfn.XLOOKUP($C10,Incrições!$D$2:$D$58,Incrições!H$2:H$58)=0,"",_xlfn.XLOOKUP($C10,Incrições!$D$2:$D$58,Incrições!H$2:H$58)) -> Gestão municipal | ... R10: =IF(_xlfn.XLOOKUP($C10,Incrições!$D$2:$D$58,Incrições!L$2:L$58)=0,"",_xlfn.XLOOKUP($C10,Incrições!$D$2:$D$58,Incrições!L$2:L$58)) -> 45924
A11: 45925.416 | B11: Clayton Gonçalves Oliva | C11: 719.914.681-72 | D11: (66)98447-3124 | E11: olivanerd@hotmail.com | F11: Sim | G11: =IF(_xlfn.XLOOKUP($C11,Incrições!$D$2:$D$58,Incrições!A$2:A$58)=0,"",_xlfn.XLOOKUP($C11,Incrições!$D$2:$D$58,Incrições!A$2:A$58)) -> 45905.706 | H11: =IF(_xlfn.XLOOKUP($C11,Incrições!$D$2:$D$58,Incrições!B$2:B$58)=0,"",_xlfn.XLOOKUP($C11,Incrições!$D$2:$D$58,Incrições!B$2:B$58)) -> clayton.oliva@edu.mt.gov.br | I11: =IF(_xlfn.XLOOKUP($C11,Incrições!$D$2:$D$58,Incrições!C$2:C$58)=0,"",_xlfn.XLOOKUP($C11,Incrições!$D$2:$D$58,Incrições!C$2:C$58)) -> Clayton Gonçalves Oliva | J11: =IF(_xlfn.XLOOKUP($C11,Incrições!$D$2:$D$58,Incrições!D$2:D$58)=0,"",_xlfn.XLOOKUP($C11,Incrições!$D$2:$D$58,Incrições!D$2:D$58)) -> 719.914.681-72 | K11: =IF(_xlfn.XLOOKUP($C11,Incrições!$D$2:$D$58,Incrições!E$2:E$58)=0,"",_xlfn.XLOOKUP($C11,Incrições!$D$2:$D$58,Incrições!E$2:E$58)) -> 29615 | L11: =IF(_xlfn.XLOOKUP($C11,Incrições!$D$2:$D$58,Incrições!F$2:F$58)=0,"",_xlfn.XLOOKUP($C11,Incrições!$D$2:$D$58,Incrições!F$2:F$58)) -> (66)98447-3124 | M11: =IF(_xlfn.XLOOKUP($C11,Incrições!$D$2:$D$58,Incrições!G$2:G$58)=0,"",_xlfn.XLOOKUP($C11,Incrições!$D$2:$D$58,Incrições!G$2:G$58)) -> Novo Santo Antônio (MT) | N11: =IF(_xlfn.XLOOKUP($C11,Incrições!$D$2:$D$58,Incrições!H$2:H$58)=0,"",_xlfn.XLOOKUP($C11,Incrições!$D$2:$D$58,Incrições!H$2:H$58)) -> Gestão municipal | ... R11: =IF(_xlfn.XLOOKUP($C11,Incrições!$D$2:$D$58,Incrições!L$2:L$58)=0,"",_xlfn.XLOOKUP($C11,Incrições!$D$2:$D$58,Incrições!L$2:L$58)) -> 45925
A12: 45924.359 | B12: Cássio Gomes Coelho | C12: 550.868.881-15 | D12: (66)99980-2994 | E12: Coelhocassiogc@gmail.com | F12: Sim | G12: =IF(_xlfn.XLOOKUP($C12,Incrições!$D$2:$D$58,Incrições!A$2:A$58)=0,"",_xlfn.XLOOKUP($C12,Incrições!$D$2:$D$58,Incrições!A$2:A$58)) -> 45909.424 | H12: =IF(_xlfn.XLOOKUP($C12,Incrições!$D$2:$D$58,Incrições!B$2:B$58)=0,"",_xlfn.XLOOKUP($C12,Incrições!$D$2:$D$58,Incrições!B$2:B$58)) -> coelhocassiogc@gmail.com | I12: =IF(_xlfn.XLOOKUP($C12,Incrições!$D$2:$D$58,Incrições!C$2:C$58)=0,"",_xlfn.XLOOKUP($C12,Incrições!$D$2:$D$58,Incrições!C$2:C$58)) -> Cássio Gomes Coelho | J12: =IF(_xlfn.XLOOKUP($C12,Incrições!$D$2:$D$58,Incrições!D$2:D$58)=0,"",_xlfn.XLOOKUP($C12,Incrições!$D$2:$D$58,Incrições!D$2:D$58)) -> 550.868.881-15 | K12: =IF(_xlfn.XLOOKUP($C12,Incrições!$D$2:$D$58,Incrições!E$2:E$58)=0,"",_xlfn.XLOOKUP($C12,Incrições!$D$2:$D$58,Incrições!E$2:E$58)) -> 25140 | L12: =IF(_xlfn.XLOOKUP($C12,Incrições!$D$2:$D$58,Incrições!F$2:F$58)=0,"",_xlfn.XLOOKUP($C12,Incrições!$D$2:$D$58,Incrições!F$2:F$58)) -> (66)99980-2994 | M12: =IF(_xlfn.XLOOKUP($C12,Incrições!$D$2:$D$58,Incrições!G$2:G$58)=0,"",_xlfn.XLOOKUP($C12,Incrições!$D$2:$D$58,Incrições!G$2:G$58)) -> Confresa (MT) | N12: =IF(_xlfn.XLOOKUP($C12,Incrições!$D$2:$D$58,Incrições!H$2:H$58)=0,"",_xlfn.XLOOKUP($C12,Incrições!$D$2:$D$58,Incrições!H$2:H$58)) -> Gestão municipal | ... R12: =IF(_xlfn.XLOOKUP($C12,Incrições!$D$2:$D$58,Incrições!L$2:L$58)=0,"",_xlfn.XLOOKUP($C12,Incrições!$D$2:$D$58,Incrições!L$2:L$58)) -> 45924
A13: 45925.359 | B13: Delcimar Vieira Lima | C13: 474.491.361-04 | D13: (66)98452-9107 | E13: delcimarvieira2@hotmail.com | F13: Sim | G13: =IF(_xlfn.XLOOKUP($C13,Incrições!$D$2:$D$58,Incrições!A$2:A$58)=0,"",_xlfn.XLOOKUP($C13,Incrições!$D$2:$D$58,Incrições!A$2:A$58)) -> 45917.324 | H13: =IF(_xlfn.XLOOKUP($C13,Incrições!$D$2:$D$58,Incrições!B$2:B$58)=0,"",_xlfn.XLOOKUP($C13,Incrições!$D$2:$D$58,Incrições!B$2:B$58)) -> delcimarvieira2@hotmail.com | I13: =IF(_xlfn.XLOOKUP($C13,Incrições!$D$2:$D$58,Incrições!C$2:C$58)=0,"",_xlfn.XLOOKUP($C13,Incrições!$D$2:$D$58,Incrições!C$2:C$58)) -> Delcimar Vieira Lima | J13: =IF(_xlfn.XLOOKUP($C13,Incrições!$D$2:$D$58,Incrições!D$2:D$58)=0,"",_xlfn.XLOOKUP($C13,Incrições!$D$2:$D$58,Incrições!D$2:D$58)) -> 474.491.361-04 | K13: =IF(_xlfn.XLOOKUP($C13,Incrições!$D$2:$D$58,Incrições!E$2:E$58)=0,"",_xlfn.XLOOKUP($C13,Incrições!$D$2:$D$58,Incrições!E$2:E$58)) -> 24860 | L13: =IF(_xlfn.XLOOKUP($C13,Incrições!$D$2:$D$58,Incrições!F$2:F$58)=0,"",_xlfn.XLOOKUP($C13,Incrições!$D$2:$D$58,Incrições!F$2:F$58)) -> (66)98452-9107 | M13: =IF(_xlfn.XLOOKUP($C13,Incrições!$D$2:$D$58,Incrições!G$2:G$58)=0,"",_xlfn.XLOOKUP($C13,Incrições!$D$2:$D$58,Incrições!G$2:G$58)) -> Canabrava do Norte (MT) | N13: =IF(_xlfn.XLOOKUP($C13,Incrições!$D$2:$D$58,Incrições!H$2:H$58)=0,"",_xlfn.XLOOKUP($C13,Incrições!$D$2:$D$58,Incrições!H$2:H$58)) -> Gestão municipal | ... R13: =IF(_xlfn.XLOOKUP($C13,Incrições!$D$2:$D$58,Incrições!L$2:L$58)=0,"",_xlfn.XLOOKUP($C13,Incrições!$D$2:$D$58,Incrições!L$2:L$58)) -> 45925
A14: 45924.357 | B14: Elaine Cintia de Souza | C14: 982.434.111-00 | D14: (66)99204-2256 | E14: elainecintia2015@gmail.com | F14: Sim | G14: =IF(_xlfn.XLOOKUP($C14,Incrições!$D$2:$D$58,Incrições!A$2:A$58)=0,"",_xlfn.XLOOKUP($C14,Incrições!$D$2:$D$58,Incrições!A$2:A$58)) -> 45915.37 | H14: =IF(_xlfn.XLOOKUP($C14,Incrições!$D$2:$D$58,Incrições!B$2:B$58)=0,"",_xlfn.XLOOKUP($C14,Incrições!$D$2:$D$58,Incrições!B$2:B$58)) -> elainecintia2015@gmail.com | I14: =IF(_xlfn.XLOOKUP($C14,Incrições!$D$2:$D$58,Incrições!C$2:C$58)=0,"",_xlfn.XLOOKUP($C14,Incrições!$D$2:$D$58,Incrições!C$2:C$58)) -> Elaine Cintia de Souza | J14: =IF(_xlfn.XLOOKUP($C14,Incrições!$D$2:$D$58,Incrições!D$2:D$58)=0,"",_xlfn.XLOOKUP($C14,Incrições!$D$2:$D$58,Incrições!D$2:D$58)) -> 982.434.111-00 | K14: =IF(_xlfn.XLOOKUP($C14,Incrições!$D$2:$D$58,Incrições!E$2:E$58)=0,"",_xlfn.XLOOKUP($C14,Incrições!$D$2:$D$58,Incrições!E$2:E$58)) -> 30146 | L14: =IF(_xlfn.XLOOKUP($C14,Incrições!$D$2:$D$58,Incrições!F$2:F$58)=0,"",_xlfn.XLOOKUP($C14,Incrições!$D$2:$D$58,Incrições!F$2:F$58)) -> (66)99204-2256 | M14: =IF(_xlfn.XLOOKUP($C14,Incrições!$D$2:$D$58,Incrições!G$2:G$58)=0,"",_xlfn.XLOOKUP($C14,Incrições!$D$2:$D$58,Incrições!G$2:G$58)) -> Pontal do Araguaia (MT) | N14: =IF(_xlfn.XLOOKUP($C14,Incrições!$D$2:$D$58,Incrições!H$2:H$58)=0,"",_xlfn.XLOOKUP($C14,Incrições!$D$2:$D$58,Incrições!H$2:H$58)) -> Gestão municipal | ... R14: =IF(_xlfn.XLOOKUP($C14,Incrições!$D$2:$D$58,Incrições!L$2:L$58)=0,"",_xlfn.XLOOKUP($C14,Incrições!$D$2:$D$58,Incrições!L$2:L$58)) -> 45924
A15: 45925.355 | B15: Eliane Romualdo Gontijo Leite | C15: 817.939.601-00 | D15: (66)98458-8018 | E15: Eliane.rl.gontijo@gmail.com | F15: Sim | G15: =IF(_xlfn.XLOOKUP($C15,Incrições!$D$2:$D$58,Incrições!A$2:A$58)=0,"",_xlfn.XLOOKUP($C15,Incrições!$D$2:$D$58,Incrições!A$2:A$58)) -> 45919.365 | H15: =IF(_xlfn.XLOOKUP($C15,Incrições!$D$2:$D$58,Incrições!B$2:B$58)=0,"",_xlfn.XLOOKUP($C15,Incrições!$D$2:$D$58,Incrições!B$2:B$58)) -> eliane.edu.tae@bomjesusdoaraguaia.mt.gov.br | I15: =IF(_xlfn.XLOOKUP($C15,Incrições!$D$2:$D$58,Incrições!C$2:C$58)=0,"",_xlfn.XLOOKUP($C15,Incrições!$D$2:$D$58,Incrições!C$2:C$58)) -> ELIANE ROMUALDO GONTIJO LEITE | J15: =IF(_xlfn.XLOOKUP($C15,Incrições!$D$2:$D$58,Incrições!D$2:D$58)=0,"",_xlfn.XLOOKUP($C15,Incrições!$D$2:$D$58,Incrições!D$2:D$58)) -> 817.939.601-00 | K15: =IF(_xlfn.XLOOKUP($C15,Incrições!$D$2:$D$58,Incrições!E$2:E$58)=0,"",_xlfn.XLOOKUP($C15,Incrições!$D$2:$D$58,Incrições!E$2:E$58)) -> 26967 | L15: =IF(_xlfn.XLOOKUP($C15,Incrições!$D$2:$D$58,Incrições!F$2:F$58)=0,"",_xlfn.XLOOKUP($C15,Incrições!$D$2:$D$58,Incrições!F$2:F$58)) -> (66)98458-8018 | M15: Vila Rica (MT) | N15: =IF(_xlfn.XLOOKUP($C15,Incrições!$D$2:$D$58,Incrições!H$2:H$58)=0,"",_xlfn.XLOOKUP($C15,Incrições!$D$2:$D$58,Incrições!H$2:H$58)) -> Gestão municipal | O15: =IF(_xlfn.XLOOKUP($C15,Incrições!$D$2:$D$58,Incrições!I$2:I$58)=0,"",_xlfn.XLOOKUP($C15,Incrições!$D$2:$D$58,Incrições!I$2:I$58)) -> Técnico Administrativo Educacional | P15: =IF(_xlfn.XLOOKUP($C15,Incrições!$D$2:$D$58,Incrições!J$2:J$58)=0,"",_xlfn.XLOOKUP($C15,Incrições!$D$2:$D$58,Incrições!J$2:J$58)) | Q15: =IF(_xlfn.XLOOKUP($C15,Incrições!$D$2:$D$58,Incrições!K$2:K$58)=0,"",_xlfn.XLOOKUP($C15,Incrições!$D$2:$D$58,Incrições!K$2:K$58)) | R15: =IF(_xlfn.XLOOKUP($C15,Incrições!$D$2:$D$58,Incrições!L$2:L$58)=0,"",_xlfn.XLOOKUP($C15,Incrições!$D$2:$D$58,Incrições!L$2:L$58)) -> 45925 | S15: =IF(_xlfn.XLOOKUP($C15,Incrições!$D$2:$D$58,Incrições!M$2:M$58)=0,"",_xlfn.XLOOKUP($C15,Incrições!$D$2:$D$58,Incrições!M$2:M$58))
A16: 45925.348 | B16: Elisabete Rosália Herrmann Brito | C16: 009.756.161-45 | D16: (66)98425-1993 | E16: elisabeteherrmann@gmail.com | F16: Sim | G16: =IF(_xlfn.XLOOKUP($C16,Incrições!$D$2:$D$58,Incrições!A$2:A$58)=0,"",_xlfn.XLOOKUP($C16,Incrições!$D$2:$D$58,Incrições!A$2:A$58)) -> 45910.576 | H16: =IF(_xlfn.XLOOKUP($C16,Incrições!$D$2:$D$58,Incrições!B$2:B$58)=0,"",_xlfn.XLOOKUP($C16,Incrições!$D$2:$D$58,Incrições!B$2:B$58)) -> elisabeteherrmann@gmail.com | I16: =IF(_xlfn.XLOOKUP($C16,Incrições!$D$2:$D$58,Incrições!C$2:C$58)=0,"",_xlfn.XLOOKUP($C16,Incrições!$D$2:$D$58,Incrições!C$2:C$58)) -> Elisabete Rosália Herrmann Brito | J16: =IF(_xlfn.XLOOKUP($C16,Incrições!$D$2:$D$58,Incrições!D$2:D$58)=0,"",_xlfn.XLOOKUP($C16,Incrições!$D$2:$D$58,Incrições!D$2:D$58)) -> 009.756.161-45 | K16: =IF(_xlfn.XLOOKUP($C16,Incrições!$D$2:$D$58,Incrições!E$2:E$58)=0,"",_xlfn.XLOOKUP($C16,Incrições!$D$2:$D$58,Incrições!E$2:E$58)) -> 31291 | L16: =IF(_xlfn.XLOOKUP($C16,Incrições!$D$2:$D$58,Incrições!F$2:F$58)=0,"",_xlfn.XLOOKUP($C16,Incrições!$D$2:$D$58,Incrições!F$2:F$58)) -> (66)98425-1993 | M16: =IF(_xlfn.XLOOKUP($C16,Incrições!$D$2:$D$58,Incrições!G$2:G$58)=0,"",_xlfn.XLOOKUP($C16,Incrições!$D$2:$D$58,Incrições!G$2:G$58)) -> Vila Rica (MT) | N16: =IF(_xlfn.XLOOKUP($C16,Incrições!$D$2:$D$58,Incrições!H$2:H$58)=0,"",_xlfn.XLOOKUP($C16,Incrições!$D$2:$D$58,Incrições!H$2:H$58)) -> CACS-FUNDEB | ... R16: =IF(_xlfn.XLOOKUP($C16,Incrições!$D$2:$D$58,Incrições!L$2:L$58)=0,"",_xlfn.XLOOKUP($C16,Incrições!$D$2:$D$58,Incrições!L$2:L$58)) -> 45925
A17: 45925.436 | B17: Gerayne Aquino Corrêa | C17: 024.883.761-32 | D17: (66)98422-7979 | E17: gerayneaquinocorrea@gmail.com | F17: Sim | G17: =IF(_xlfn.XLOOKUP($C17,Incrições!$D$2:$D$58,Incrições!A$2:A$58)=0,"",_xlfn.XLOOKUP($C17,Incrições!$D$2:$D$58,Incrições!A$2:A$58)) -> 45915.571 | H17: =IF(_xlfn.XLOOKUP($C17,Incrições!$D$2:$D$58,Incrições!B$2:B$58)=0,"",_xlfn.XLOOKUP($C17,Incrições!$D$2:$D$58,Incrições!B$2:B$58)) -> gerayneaquinocorrea@gmail.com | I17: =IF(_xlfn.XLOOKUP($C17,Incrições!$D$2:$D$58,Incrições!C$2:C$58)=0,"",_xlfn.XLOOKUP($C17,Incrições!$D$2:$D$58,Incrições!C$2:C$58)) -> Gerayne Aquino Corrêa | J17: =IF(_xlfn.XLOOKUP($C17,Incrições!$D$2:$D$58,Incrições!D$2:D$58)=0,"",_xlfn.XLOOKUP($C17,Incrições!$D$2:$D$58,Incrições!D$2:D$58)) -> 024.883.761-32 | K17: =IF(_xlfn.XLOOKUP($C17,Incrições!$D$2:$D$58,Incrições!E$2:E$58)=0,"",_xlfn.XLOOKUP($C17,Incrições!$D$2:$D$58,Incrições!E$2:E$58)) -> 32412 | L17: =IF(_xlfn.XLOOKUP($C17,Incrições!$D$2:$D$58,Incrições!F$2:F$58)=0,"",_xlfn.XLOOKUP($C17,Incrições!$D$2:$D$58,Incrições!F$2:F$58)) -> (66)98422-7979 | M17: =IF(_xlfn.XLOOKUP($C17,Incrições!$D$2:$D$58,Incrições!G$2:G$58)=0,"",_xlfn.XLOOKUP($C17,Incrições!$D$2:$D$58,Incrições!G$2:G$58)) -> Araguaiana (MT) | N17: =IF(_xlfn.XLOOKUP($C17,Incrições!$D$2:$D$58,Incrições!H$2:H$58)=0,"",_xlfn.XLOOKUP($C17,Incrições!$D$2:$D$58,Incrições!H$2:H$58)) -> Gestão municipal | ... S17: =IF(_xlfn.XLOOKUP($C17,Incrições!$D$2:$D$58,Incrições!M$2:M$58)=0,"",_xlfn.XLOOKUP($C17,Incrições!$D$2:$D$58,Incrições!M$2:M$58))
A18: 45925.355 | B18: Adriane Hilario santos | C18: 822.671.541-53 | D18: (66)98446-0280 | E18: Adrianehilariosantos15@gmail.com | F18: Sim | G18: =IF(_xlfn.XLOOKUP($C18,Incrições!$D$2:$D$58,Incrições!A$2:A$58)=0,"",_xlfn.XLOOKUP($C18,Incrições!$D$2:$D$58,Incrições!A$2:A$58)) -> 45908.708 | H18: =IF(_xlfn.XLOOKUP($C18,Incrições!$D$2:$D$58,Incrições!B$2:B$58)=0,"",_xlfn.XLOOKUP($C18,Incrições!$D$2:$D$58,Incrições!B$2:B$58)) -> ggaragemeducacao@gmail.com | I18: =IF(_xlfn.XLOOKUP($C18,Incrições!$D$2:$D$58,Incrições!C$2:C$58)=0,"",_xlfn.XLOOKUP($C18,Incrições!$D$2:$D$58,Incrições!C$2:C$58)) -> Adriane hilario santos | J18: =IF(_xlfn.XLOOKUP($C18,Incrições!$D$2:$D$58,Incrições!D$2:D$58)=0,"",_xlfn.XLOOKUP($C18,Incrições!$D$2:$D$58,Incrições!D$2:D$58)) -> 822.671.541-53 | K18: =IF(_xlfn.XLOOKUP($C18,Incrições!$D$2:$D$58,Incrições!E$2:E$58)=0,"",_xlfn.XLOOKUP($C18,Incrições!$D$2:$D$58,Incrições!E$2:E$58)) -> 27294 | L18: =IF(_xlfn.XLOOKUP($C18,Incrições!$D$2:$D$58,Incrições!F$2:F$58)=0,"",_xlfn.XLOOKUP($C18,Incrições!$D$2:$D$58,Incrições!F$2:F$58)) -> (66)98152-0154 | M18: Vila Rica (MT) | N18: =IF(_xlfn.XLOOKUP($C18,Incrições!$D$2:$D$58,Incrições!H$2:H$58)=0,"",_xlfn.XLOOKUP($C18,Incrições!$D$2:$D$58,Incrições!H$2:H$58)) -> Gestão municipal | O18: =IF(_xlfn.XLOOKUP($C18,Incrições!$D$2:$D$58,Incrições!I$2:I$58)=0,"",_xlfn.XLOOKUP($C18,Incrições!$D$2:$D$58,Incrições!I$2:I$58)) -> Secretaria | P18: =IF(_xlfn.XLOOKUP($C18,Incrições!$D$2:$D$58,Incrições!J$2:J$58)=0,"",_xlfn.XLOOKUP($C18,Incrições!$D$2:$D$58,Incrições!J$2:J$58)) -> Sim | Q18: =IF(_xlfn.XLOOKUP($C18,Incrições!$D$2:$D$58,Incrições!K$2:K$58)=0,"",_xlfn.XLOOKUP($C18,Incrições!$D$2:$D$58,Incrições!K$2:K$58)) | R18: =IF(_xlfn.XLOOKUP($C18,Incrições!$D$2:$D$58,Incrições!L$2:L$58)=0,"",_xlfn.XLOOKUP($C18,Incrições!$D$2:$D$58,Incrições!L$2:L$58)) -> 45925 | S18: =IF(_xlfn.XLOOKUP($C18,Incrições!$D$2:$D$58,Incrições!M$2:M$58)=0,"",_xlfn.XLOOKUP($C18,Incrições!$D$2:$D$58,Incrições!M$2:M$58))
A19: 45924.363 | B19: Ketlenn Jaklynny Alves dos Santos | C19: 053.782.371-90 | D19: (66)99964-3865 | E19: Jaklynny2009@hotmail.com | F19: Sim | G19: =IF(_xlfn.XLOOKUP($C19,Incrições!$D$2:$D$58,Incrições!A$2:A$58)=0,"",_xlfn.XLOOKUP($C19,Incrições!$D$2:$D$58,Incrições!A$2:A$58)) -> 45914.652 | H19: =IF(_xlfn.XLOOKUP($C19,Incrições!$D$2:$D$58,Incrições!B$2:B$58)=0,"",_xlfn.XLOOKUP($C19,Incrições!$D$2:$D$58,Incrições!B$2:B$58)) -> jaklynny2009@hotmail.com | I19: =IF(_xlfn.XLOOKUP($C19,Incrições!$D$2:$D$58,Incrições!C$2:C$58)=0,"",_xlfn.XLOOKUP($C19,Incrições!$D$2:$D$58,Incrições!C$2:C$58)) -> Ketlen Jaklynny Alves dos Santos | J19: =IF(_xlfn.XLOOKUP($C19,Incrições!$D$2:$D$58,Incrições!D$2:D$58)=0,"",_xlfn.XLOOKUP($C19,Incrições!$D$2:$D$58,Incrições!D$2:D$58)) -> 053.782.371-90 | K19: =IF(_xlfn.XLOOKUP($C19,Incrições!$D$2:$D$58,Incrições!E$2:E$58)=0,"",_xlfn.XLOOKUP($C19,Incrições!$D$2:$D$58,Incrições!E$2:E$58)) -> 34708 | L19: =IF(_xlfn.XLOOKUP($C19,Incrições!$D$2:$D$58,Incrições!F$2:F$58)=0,"",_xlfn.XLOOKUP($C19,Incrições!$D$2:$D$58,Incrições!F$2:F$58)) -> (66)99964-3865 | M19: =IF(_xlfn.XLOOKUP($C19,Incrições!$D$2:$D$58,Incrições!G$2:G$58)=0,"",_xlfn.XLOOKUP($C19,Incrições!$D$2:$D$58,Incrições!G$2:G$58)) -> Água Boa (MT) | N19: =IF(_xlfn.XLOOKUP($C19,Incrições!$D$2:$D$58,Incrições!H$2:H$58)=0,"",_xlfn.XLOOKUP($C19,Incrições!$D$2:$D$58,Incrições!H$2:H$58)) -> Gestão municipal | ... R19: =IF(_xlfn.XLOOKUP($C19,Incrições!$D$2:$D$58,Incrições!L$2:L$58)=0,"",_xlfn.XLOOKUP($C19,Incrições!$D$2:$D$58,Incrições!L$2:L$58)) -> 45924
A20: 45924.359 | B20: João Carlos Araújo Rodrigues | C20: 048.318.311-31 | D20: (66)99698-6788 | E20: joaocarlos.ac621@gmail.com | F20: Sim | G20: =IF(_xlfn.XLOOKUP($C20,Incrições!$D$2:$D$58,Incrições!A$2:A$58)=0,"",_xlfn.XLOOKUP($C20,Incrições!$D$2:$D$58,Incrições!A$2:A$58)) -> 45909.384 | H20: =IF(_xlfn.XLOOKUP($C20,Incrições!$D$2:$D$58,Incrições!B$2:B$58)=0,"",_xlfn.XLOOKUP($C20,Incrições!$D$2:$D$58,Incrições!B$2:B$58)) -> joaocarlos.ac621@gmail.com | I20: =IF(_xlfn.XLOOKUP($C20,Incrições!$D$2:$D$58,Incrições!C$2:C$58)=0,"",_xlfn.XLOOKUP($C20,Incrições!$D$2:$D$58,Incrições!C$2:C$58)) -> João Carlos Araujo Rodrigues | J20: =IF(_xlfn.XLOOKUP($C20,Incrições!$D$2:$D$58,Incrições!D$2:D$58)=0,"",_xlfn.XLOOKUP($C20,Incrições!$D$2:$D$58,Incrições!D$2:D$58)) -> 048.318.311-31 | K20: =IF(_xlfn.XLOOKUP($C20,Incrições!$D$2:$D$58,Incrições!E$2:E$58)=0,"",_xlfn.XLOOKUP($C20,Incrições!$D$2:$D$58,Incrições!E$2:E$58)) -> 35699 | L20: =IF(_xlfn.XLOOKUP($C20,Incrições!$D$2:$D$58,Incrições!F$2:F$58)=0,"",_xlfn.XLOOKUP($C20,Incrições!$D$2:$D$58,Incrições!F$2:F$58)) -> (66)99698-6788 | M20: =IF(_xlfn.XLOOKUP($C20,Incrições!$D$2:$D$58,Incrições!G$2:G$58)=0,"",_xlfn.XLOOKUP($C20,Incrições!$D$2:$D$58,Incrições!G$2:G$58)) -> Confresa (MT) | N20: =IF(_xlfn.XLOOKUP($C20,Incrições!$D$2:$D$58,Incrições!H$2:H$58)=0,"",_xlfn.XLOOKUP($C20,Incrições!$D$2:$D$58,Incrições!H$2:H$58)) -> Gestão municipal | ... R20: =IF(_xlfn.XLOOKUP($C20,Incrições!$D$2:$D$58,Incrições!L$2:L$58)=0,"",_xlfn.XLOOKUP($C20,Incrições!$D$2:$D$58,Incrições!L$2:L$58)) -> 45924
A21: 45925.36 | B21: Josimeire de Souza Ramos Resende | C21: 004.763.191-02 | D21: (66)98433-8186 | E21: josimeire_quimica2011@hotmail.com | F21: Sim | G21: =IF(_xlfn.XLOOKUP($C21,Incrições!$D$2:$D$58,Incrições!A$2:A$58)=0,"",_xlfn.XLOOKUP($C21,Incrições!$D$2:$D$58,Incrições!A$2:A$58)) -> 45925.358 | H21: =IF(_xlfn.XLOOKUP($C21,Incrições!$D$2:$D$58,Incrições!B$2:B$58)=0,"",_xlfn.XLOOKUP($C21,Incrições!$D$2:$D$58,Incrições!B$2:B$58)) -> josimeire_quimica2011@hotmail.com | I21: =IF(_xlfn.XLOOKUP($C21,Incrições!$D$2:$D$58,Incrições!C$2:C$58)=0,"",_xlfn.XLOOKUP($C21,Incrições!$D$2:$D$58,Incrições!C$2:C$58)) -> Josimeire de Souza Ramos Resende | J21: =IF(_xlfn.XLOOKUP($C21,Incrições!$D$2:$D$58,Incrições!D$2:D$58)=0,"",_xlfn.XLOOKUP($C21,Incrições!$D$2:$D$58,Incrições!D$2:D$58)) -> 004.763.191-02 | K21: =IF(_xlfn.XLOOKUP($C21,Incrições!$D$2:$D$58,Incrições!E$2:E$58)=0,"",_xlfn.XLOOKUP($C21,Incrições!$D$2:$D$58,Incrições!E$2:E$58)) -> 30616 | L21: =IF(_xlfn.XLOOKUP($C21,Incrições!$D$2:$D$58,Incrições!F$2:F$58)=0,"",_xlfn.XLOOKUP($C21,Incrições!$D$2:$D$58,Incrições!F$2:F$58)) -> (66)98433-8186 | M21: =IF(_xlfn.XLOOKUP($C21,Incrições!$D$2:$D$58,Incrições!G$2:G$58)=0,"",_xlfn.XLOOKUP($C21,Incrições!$D$2:$D$58,Incrições!G$2:G$58)) -> Canabrava do Norte (MT) | N21: =IF(_xlfn.XLOOKUP($C21,Incrições!$D$2:$D$58,Incrições!H$2:H$58)=0,"",_xlfn.XLOOKUP($C21,Incrições!$D$2:$D$58,Incrições!H$2:H$58)) -> Gestão municipal | ... R21: =IF(_xlfn.XLOOKUP($C21,Incrições!$D$2:$D$58,Incrições!L$2:L$58)=0,"",_xlfn.XLOOKUP($C21,Incrições!$D$2:$D$58,Incrições!L$2:L$58)) -> 45925
A22: 45924.368 | B22: Kamili Alexandre | C22: 060.440.811-09 | D22: (66)99204-7193 | E22: Kamilifitdance@gmail.com | F22: Sim | G22: =IF(_xlfn.XLOOKUP($C22,Incrições!$D$2:$D$58,Incrições!A$2:A$58)=0,"",_xlfn.XLOOKUP($C22,Incrições!$D$2:$D$58,Incrições!A$2:A$58)) -> 45916.687 | H22: =IF(_xlfn.XLOOKUP($C22,Incrições!$D$2:$D$58,Incrições!B$2:B$58)=0,"",_xlfn.XLOOKUP($C22,Incrições!$D$2:$D$58,Incrições!B$2:B$58)) -> kamilifitdance@gmail.com | I22: =IF(_xlfn.XLOOKUP($C22,Incrições!$D$2:$D$58,Incrições!C$2:C$58)=0,"",_xlfn.XLOOKUP($C22,Incrições!$D$2:$D$58,Incrições!C$2:C$58)) -> kamili alexandre | J22: =IF(_xlfn.XLOOKUP($C22,Incrições!$D$2:$D$58,Incrições!D$2:D$58)=0,"",_xlfn.XLOOKUP($C22,Incrições!$D$2:$D$58,Incrições!D$2:D$58)) -> 060.440.811-09 | K22: =IF(_xlfn.XLOOKUP($C22,Incrições!$D$2:$D$58,Incrições!E$2:E$58)=0,"",_xlfn.XLOOKUP($C22,Incrições!$D$2:$D$58,Incrições!E$2:E$58)) -> 38005 | L22: =IF(_xlfn.XLOOKUP($C22,Incrições!$D$2:$D$58,Incrições!F$2:F$58)=0,"",_xlfn.XLOOKUP($C22,Incrições!$D$2:$D$58,Incrições!F$2:F$58)) -> (66)99204-7193 | M22: =IF(_xlfn.XLOOKUP($C22,Incrições!$D$2:$D$58,Incrições!G$2:G$58)=0,"",_xlfn.XLOOKUP($C22,Incrições!$D$2:$D$58,Incrições!G$2:G$58)) -> Querência (MT) | N22: =IF(_xlfn.XLOOKUP($C22,Incrições!$D$2:$D$58,Incrições!H$2:H$58)=0,"",_xlfn.XLOOKUP($C22,Incrições!$D$2:$D$58,Incrições!H$2:H$58)) -> Gestão municipal | ... R22: =IF(_xlfn.XLOOKUP($C22,Incrições!$D$2:$D$58,Incrições!L$2:L$58)=0,"",_xlfn.XLOOKUP($C22,Incrições!$D$2:$D$58,Incrições!L$2:L$58)) -> 45924
A23: 45925.354 | B23: Kate Regina Paulo da Silva | C23: 762.162.171-00 | D23: (66)98437-1064 | E23: Katereginaps2@hotmail.com | F23: Sim | G23: =IF(_xlfn.XLOOKUP($C23,Incrições!$D$2:$D$58,Incrições!A$2:A$58)=0,"",_xlfn.XLOOKUP($C23,Incrições!$D$2:$D$58,Incrições!A$2:A$58)) -> 45918.886 | H23: =IF(_xlfn.XLOOKUP($C23,Incrições!$D$2:$D$58,Incrições!B$2:B$58)=0,"",_xlfn.XLOOKUP($C23,Incrições!$D$2:$D$58,Incrições!B$2:B$58)) -> Katereginaps2@hotmail.com | I23: =IF(_xlfn.XLOOKUP($C23,Incrições!$D$2:$D$58,Incrições!C$2:C$58)=0,"",_xlfn.XLOOKUP($C23,Incrições!$D$2:$D$58,Incrições!C$2:C$58)) -> Kate Regina Paulo da Silva | J23: =IF(_xlfn.XLOOKUP($C23,Incrições!$D$2:$D$58,Incrições!D$2:D$58)=0,"",_xlfn.XLOOKUP($C23,Incrições!$D$2:$D$58,Incrições!D$2:D$58)) -> 762.162.171-00 | K23: =IF(_xlfn.XLOOKUP($C23,Incrições!$D$2:$D$58,Incrições!E$2:E$58)=0,"",_xlfn.XLOOKUP($C23,Incrições!$D$2:$D$58,Incrições!E$2:E$58)) -> 27522 | L23: =IF(_xlfn.XLOOKUP($C23,Incrições!$D$2:$D$58,Incrições!F$2:F$58)=0,"",_xlfn.XLOOKUP($C23,Incrições!$D$2:$D$58,Incrições!F$2:F$58)) -> (66)98437-1064 | M23: =IF(_xlfn.XLOOKUP($C23,Incrições!$D$2:$D$58,Incrições!G$2:G$58)=0,"",_xlfn.XLOOKUP($C23,Incrições!$D$2:$D$58,Incrições!G$2:G$58)) -> Bom Jesus do Araguaia (MT) | N23: =IF(_xlfn.XLOOKUP($C23,Incrições!$D$2:$D$58,Incrições!H$2:H$58)=0,"",_xlfn.XLOOKUP($C23,Incrições!$D$2:$D$58,Incrições!H$2:H$58)) -> Gestão municipal | ... R23: =IF(_xlfn.XLOOKUP($C23,Incrições!$D$2:$D$58,Incrições!L$2:L$58)=0,"",_xlfn.XLOOKUP($C23,Incrições!$D$2:$D$58,Incrições!L$2:L$58)) -> 45925
A24: 45924.368 | B24: KELLEN MARINA KLEIN ROSSATO | C24: 038.713.381-09 | D24: (66)99714-0657 | E24: kellenkleinrossato@gmail.com | F24: Sim | G24: =IF(_xlfn.XLOOKUP($C24,Incrições!$D$2:$D$58,Incrições!A$2:A$58)=0,"",_xlfn.XLOOKUP($C24,Incrições!$D$2:$D$58,Incrições!A$2:A$58)) -> 45916.69 | H24: =IF(_xlfn.XLOOKUP($C24,Incrições!$D$2:$D$58,Incrições!B$2:B$58)=0,"",_xlfn.XLOOKUP($C24,Incrições!$D$2:$D$58,Incrições!B$2:B$58)) -> kellenkleinrossato@gmail.com | I24: =IF(_xlfn.XLOOKUP($C24,Incrições!$D$2:$D$58,Incrições!C$2:C$58)=0,"",_xlfn.XLOOKUP($C24,Incrições!$D$2:$D$58,Incrições!C$2:C$58)) -> KELLEN MARINA KLEIN ROSSATO | J24: =IF(_xlfn.XLOOKUP($C24,Incrições!$D$2:$D$58,Incrições!D$2:D$58)=0,"",_xlfn.XLOOKUP($C24,Incrições!$D$2:$D$58,Incrições!D$2:D$58)) -> 038.713.381-09 | K24: =IF(_xlfn.XLOOKUP($C24,Incrições!$D$2:$D$58,Incrições!E$2:E$58)=0,"",_xlfn.XLOOKUP($C24,Incrições!$D$2:$D$58,Incrições!E$2:E$58)) -> 33507 | L24: =IF(_xlfn.XLOOKUP($C24,Incrições!$D$2:$D$58,Incrições!F$2:F$58)=0,"",_xlfn.XLOOKUP($C24,Incrições!$D$2:$D$58,Incrições!F$2:F$58)) -> (66)99714-0657 | M24: =IF(_xlfn.XLOOKUP($C24,Incrições!$D$2:$D$58,Incrições!G$2:G$58)=0,"",_xlfn.XLOOKUP($C24,Incrições!$D$2:$D$58,Incrições!G$2:G$58)) -> Querência (MT) | N24: =IF(_xlfn.XLOOKUP($C24,Incrições!$D$2:$D$58,Incrições!H$2:H$58)=0,"",_xlfn.XLOOKUP($C24,Incrições!$D$2:$D$58,Incrições!H$2:H$58)) -> CACS-FUNDEB | ... R24: =IF(_xlfn.XLOOKUP($C24,Incrições!$D$2:$D$58,Incrições!L$2:L$58)=0,"",_xlfn.XLOOKUP($C24,Incrições!$D$2:$D$58,Incrições!L$2:L$58)) -> 45924
A25: 45924.359 | B25: Alexandre Lanusse Pereira Dias | C25: 617.215.221-15 | D25: (66)99988-9196 | E25: Lanusseblz@hotmail.com | F25: Sim | G25: =IF(_xlfn.XLOOKUP($C25,Incrições!$D$2:$D$58,Incrições!A$2:A$58)=0,"",_xlfn.XLOOKUP($C25,Incrições!$D$2:$D$58,Incrições!A$2:A$58)) -> 45905.432 | H25: =IF(_xlfn.XLOOKUP($C25,Incrições!$D$2:$D$58,Incrições!B$2:B$58)=0,"",_xlfn.XLOOKUP($C25,Incrições!$D$2:$D$58,Incrições!B$2:B$58)) -> lanusseblz@hotmail.com | I25: =IF(_xlfn.XLOOKUP($C25,Incrições!$D$2:$D$58,Incrições!C$2:C$58)=0,"",_xlfn.XLOOKUP($C25,Incrições!$D$2:$D$58,Incrições!C$2:C$58)) -> Alexandre Lanusse Pereira Dias | J25: =IF(_xlfn.XLOOKUP($C25,Incrições!$D$2:$D$58,Incrições!D$2:D$58)=0,"",_xlfn.XLOOKUP($C25,Incrições!$D$2:$D$58,Incrições!D$2:D$58)) -> 617.215.221-15 | K25: =IF(_xlfn.XLOOKUP($C25,Incrições!$D$2:$D$58,Incrições!E$2:E$58)=0,"",_xlfn.XLOOKUP($C25,Incrições!$D$2:$D$58,Incrições!E$2:E$58)) -> 26507 | L25: =IF(_xlfn.XLOOKUP($C25,Incrições!$D$2:$D$58,Incrições!F$2:F$58)=0,"",_xlfn.XLOOKUP($C25,Incrições!$D$2:$D$58,Incrições!F$2:F$58)) -> (66)99988-9196 | M25: =IF(_xlfn.XLOOKUP($C25,Incrições!$D$2:$D$58,Incrições!G$2:G$58)=0,"",_xlfn.XLOOKUP($C25,Incrições!$D$2:$D$58,Incrições!G$2:G$58)) -> Baliza (GO) | N25: =IF(_xlfn.XLOOKUP($C25,Incrições!$D$2:$D$58,Incrições!H$2:H$58)=0,"",_xlfn.XLOOKUP($C25,Incrições!$D$2:$D$58,Incrições!H$2:H$58)) -> Gestão municipal | ... R25: =IF(_xlfn.XLOOKUP($C25,Incrições!$D$2:$D$58,Incrições!L$2:L$58)=0,"",_xlfn.XLOOKUP($C25,Incrições!$D$2:$D$58,Incrições!L$2:L$58)) -> 45924
A26: 45925.454 | B26: Lídia Arraes de Oliveira | C26: 395.707.701-04 | D26: (66)98422-5865 | E26: lidiaarraes01@hotmail.com | F26: Sim | G26: =IF(_xlfn.XLOOKUP($C26,Incrições!$D$2:$D$58,Incrições!A$2:A$58)=0,"",_xlfn.XLOOKUP($C26,Incrições!$D$2:$D$58,Incrições!A$2:A$58)) -> 45917.469 | H26: =IF(_xlfn.XLOOKUP($C26,Incrições!$D$2:$D$58,Incrições!B$2:B$58)=0,"",_xlfn.XLOOKUP($C26,Incrições!$D$2:$D$58,Incrições!B$2:B$58)) -> lidiaarraes01@hotmail.com | I26: =IF(_xlfn.XLOOKUP($C26,Incrições!$D$2:$D$58,Incrições!C$2:C$58)=0,"",_xlfn.XLOOKUP($C26,Incrições!$D$2:$D$58,Incrições!C$2:C$58)) -> Lídia Arraes de Oliveira | J26: =IF(_xlfn.XLOOKUP($C26,Incrições!$D$2:$D$58,Incrições!D$2:D$58)=0,"",_xlfn.XLOOKUP($C26,Incrições!$D$2:$D$58,Incrições!D$2:D$58)) -> 395.707.701-04 | K26: =IF(_xlfn.XLOOKUP($C26,Incrições!$D$2:$D$58,Incrições!E$2:E$58)=0,"",_xlfn.XLOOKUP($C26,Incrições!$D$2:$D$58,Incrições!E$2:E$58)) -> 22070 | L26: =IF(_xlfn.XLOOKUP($C26,Incrições!$D$2:$D$58,Incrições!F$2:F$58)=0,"",_xlfn.XLOOKUP($C26,Incrições!$D$2:$D$58,Incrições!F$2:F$58)) -> (66)98422-5865 | M26: =IF(_xlfn.XLOOKUP($C26,Incrições!$D$2:$D$58,Incrições!G$2:G$58)=0,"",_xlfn.XLOOKUP($C26,Incrições!$D$2:$D$58,Incrições!G$2:G$58)) -> Araguaiana (MT) | N26: =IF(_xlfn.XLOOKUP($C26,Incrições!$D$2:$D$58,Incrições!H$2:H$58)=0,"",_xlfn.XLOOKUP($C26,Incrições!$D$2:$D$58,Incrições!H$2:H$58)) -> CACS-FUNDEB | ... R26: =IF(_xlfn.XLOOKUP($C26,Incrições!$D$2:$D$58,Incrições!L$2:L$58)=0,"",_xlfn.XLOOKUP($C26,Incrições!$D$2:$D$58,Incrições!L$2:L$58)) -> 45925
A27: 45925.359 | B27: Lorena Pereira de Souza | C27: 042.254.611-90 | D27: (66)99241-6958 | E27: lorennasouza09.ls@gmail.com | F27: Sim | G27: =IF(_xlfn.XLOOKUP($C27,Incrições!$D$2:$D$58,Incrições!A$2:A$58)=0,"",_xlfn.XLOOKUP($C27,Incrições!$D$2:$D$58,Incrições!A$2:A$58)) -> 45924.673 | H27: =IF(_xlfn.XLOOKUP($C27,Incrições!$D$2:$D$58,Incrições!B$2:B$58)=0,"",_xlfn.XLOOKUP($C27,Incrições!$D$2:$D$58,Incrições!B$2:B$58)) -> lorennasouza09.ls@gmail.com | I27: =IF(_xlfn.XLOOKUP($C27,Incrições!$D$2:$D$58,Incrições!C$2:C$58)=0,"",_xlfn.XLOOKUP($C27,Incrições!$D$2:$D$58,Incrições!C$2:C$58)) -> Lorena Pereira de Souza | J27: =IF(_xlfn.XLOOKUP($C27,Incrições!$D$2:$D$58,Incrições!D$2:D$58)=0,"",_xlfn.XLOOKUP($C27,Incrições!$D$2:$D$58,Incrições!D$2:D$58)) -> 042.254.611-90 | K27: =IF(_xlfn.XLOOKUP($C27,Incrições!$D$2:$D$58,Incrições!E$2:E$58)=0,"",_xlfn.XLOOKUP($C27,Incrições!$D$2:$D$58,Incrições!E$2:E$58)) -> 34029 | L27: =IF(_xlfn.XLOOKUP($C27,Incrições!$D$2:$D$58,Incrições!F$2:F$58)=0,"",_xlfn.XLOOKUP($C27,Incrições!$D$2:$D$58,Incrições!F$2:F$58)) -> (66)99241-6958 | M27: =IF(_xlfn.XLOOKUP($C27,Incrições!$D$2:$D$58,Incrições!G$2:G$58)=0,"",_xlfn.XLOOKUP($C27,Incrições!$D$2:$D$58,Incrições!G$2:G$58)) -> Barra do Garças (MT) | N27: =IF(_xlfn.XLOOKUP($C27,Incrições!$D$2:$D$58,Incrições!H$2:H$58)=0,"",_xlfn.XLOOKUP($C27,Incrições!$D$2:$D$58,Incrições!H$2:H$58)) -> Gestão municipal | ... R27: =IF(_xlfn.XLOOKUP($C27,Incrições!$D$2:$D$58,Incrições!L$2:L$58)=0,"",_xlfn.XLOOKUP($C27,Incrições!$D$2:$D$58,Incrições!L$2:L$58)) -> 45925
A28: 45925.348 | B28: Marcos Luiz de Jesus Silva Rachid | C28: 002.145.951-70 | D28: (66)99979-9371 | E28: marcosrachid93@gmail.com | F28: Sim | G28: =IF(_xlfn.XLOOKUP($C28,Incrições!$D$2:$D$58,Incrições!A$2:A$58)=0,"",_xlfn.XLOOKUP($C28,Incrições!$D$2:$D$58,Incrições!A$2:A$58)) -> 45908.469 | H28: =IF(_xlfn.XLOOKUP($C28,Incrições!$D$2:$D$58,Incrições!B$2:B$58)=0,"",_xlfn.XLOOKUP($C28,Incrições!$D$2:$D$58,Incrições!B$2:B$58)) -> marcosrachid93@gmail.com | I28: =IF(_xlfn.XLOOKUP($C28,Incrições!$D$2:$D$58,Incrições!C$2:C$58)=0,"",_xlfn.XLOOKUP($C28,Incrições!$D$2:$D$58,Incrições!C$2:C$58)) -> Marcos Luiz de Jesus Silva Rachid | J28: =IF(_xlfn.XLOOKUP($C28,Incrições!$D$2:$D$58,Incrições!D$2:D$58)=0,"",_xlfn.XLOOKUP($C28,Incrições!$D$2:$D$58,Incrições!D$2:D$58)) -> 002.145.951-70 | K28: =IF(_xlfn.XLOOKUP($C28,Incrições!$D$2:$D$58,Incrições!E$2:E$58)=0,"",_xlfn.XLOOKUP($C28,Incrições!$D$2:$D$58,Incrições!E$2:E$58)) -> 31275 | L28: =IF(_xlfn.XLOOKUP($C28,Incrições!$D$2:$D$58,Incrições!F$2:F$58)=0,"",_xlfn.XLOOKUP($C28,Incrições!$D$2:$D$58,Incrições!F$2:F$58)) -> (66)98426-3841 | M28: =IF(_xlfn.XLOOKUP($C28,Incrições!$D$2:$D$58,Incrições!G$2:G$58)=0,"",_xlfn.XLOOKUP($C28,Incrições!$D$2:$D$58,Incrições!G$2:G$58)) -> São Félix do Araguaia (MT) | N28: =IF(_xlfn.XLOOKUP($C28,Incrições!$D$2:$D$58,Incrições!H$2:H$58)=0,"",_xlfn.XLOOKUP($C28,Incrições!$D$2:$D$58,Incrições!H$2:H$58)) -> CACS-FUNDEB | ... R28: =IF(_xlfn.XLOOKUP($C28,Incrições!$D$2:$D$58,Incrições!L$2:L$58)=0,"",_xlfn.XLOOKUP($C28,Incrições!$D$2:$D$58,Incrições!L$2:L$58)) -> 45925
A29: 45924.357 | B29: MARIA JOSE LEANDRO DE ALMEIDA OLIVEIRA | C29: 987.429.811-15 | D29: (66)98443-4363 | E29: marialeandro@portoalegredonorte.mt.gov.br | F29: Sim | G29: =IF(_xlfn.XLOOKUP($C29,Incrições!$D$2:$D$58,Incrições!A$2:A$58)=0,"",_xlfn.XLOOKUP($C29,Incrições!$D$2:$D$58,Incrições!A$2:A$58)) -> 45912.431 | H29: =IF(_xlfn.XLOOKUP($C29,Incrições!$D$2:$D$58,Incrições!B$2:B$58)=0,"",_xlfn.XLOOKUP($C29,Incrições!$D$2:$D$58,Incrições!B$2:B$58)) -> marialeandro@portoalegredonorte.mt.gov.br | I29: =IF(_xlfn.XLOOKUP($C29,Incrições!$D$2:$D$58,Incrições!C$2:C$58)=0,"",_xlfn.XLOOKUP($C29,Incrições!$D$2:$D$58,Incrições!C$2:C$58)) -> MARIA JOSE LEANDRO DE ALMEIDA OLIVEIRA | J29: =IF(_xlfn.XLOOKUP($C29,Incrições!$D$2:$D$58,Incrições!D$2:D$58)=0,"",_xlfn.XLOOKUP($C29,Incrições!$D$2:$D$58,Incrições!D$2:D$58)) -> 987.429.811-15 | K29: =IF(_xlfn.XLOOKUP($C29,Incrições!$D$2:$D$58,Incrições!E$2:E$58)=0,"",_xlfn.XLOOKUP($C29,Incrições!$D$2:$D$58,Incrições!E$2:E$58)) -> 30578 | L29: =IF(_xlfn.XLOOKUP($C29,Incrições!$D$2:$D$58,Incrições!F$2:F$58)=0,"",_xlfn.XLOOKUP($C29,Incrições!$D$2:$D$58,Incrições!F$2:F$58)) -> (66)98418-4363 | M29: =IF(_xlfn.XLOOKUP($C29,Incrições!$D$2:$D$58,Incrições!G$2:G$58)=0,"",_xlfn.XLOOKUP($C29,Incrições!$D$2:$D$58,Incrições!G$2:G$58)) -> Porto Alegre do Norte (MT) | N29: =IF(_xlfn.XLOOKUP($C29,Incrições!$D$2:$D$58,Incrições!H$2:H$58)=0,"",_xlfn.XLOOKUP($C29,Incrições!$D$2:$D$58,Incrições!H$2:H$58)) -> CACS-FUNDEB | ... R29: =IF(_xlfn.XLOOKUP($C29,Incrições!$D$2:$D$58,Incrições!L$2:L$58)=0,"",_xlfn.XLOOKUP($C29,Incrições!$D$2:$D$58,Incrições!L$2:L$58)) -> 45924
A30: 45924.363 | B30: Fábio Pinto De Oliveira | C30: 643.714.921-34 | D30: (62)99987-2626 | E30: Mcgfabio@gmail.com | F30: Sim | G30: =IF(_xlfn.XLOOKUP($C30,Incrições!$D$2:$D$58,Incrições!A$2:A$58)=0,"",_xlfn.XLOOKUP($C30,Incrições!$D$2:$D$58,Incrições!A$2:A$58)) -> 45911.548 | H30: =IF(_xlfn.XLOOKUP($C30,Incrições!$D$2:$D$58,Incrições!B$2:B$58)=0,"",_xlfn.XLOOKUP($C30,Incrições!$D$2:$D$58,Incrições!B$2:B$58)) -> mcgfabio@gmail.com | I30: =IF(_xlfn.XLOOKUP($C30,Incrições!$D$2:$D$58,Incrições!C$2:C$58)=0,"",_xlfn.XLOOKUP($C30,Incrições!$D$2:$D$58,Incrições!C$2:C$58)) -> Fábio Pinto de Oliveira | J30: =IF(_xlfn.XLOOKUP($C30,Incrições!$D$2:$D$58,Incrições!D$2:D$58)=0,"",_xlfn.XLOOKUP($C30,Incrições!$D$2:$D$58,Incrições!D$2:D$58)) -> 643.714.921-34 | K30: =IF(_xlfn.XLOOKUP($C30,Incrições!$D$2:$D$58,Incrições!E$2:E$58)=0,"",_xlfn.XLOOKUP($C30,Incrições!$D$2:$D$58,Incrições!E$2:E$58)) -> 26116 | L30: =IF(_xlfn.XLOOKUP($C30,Incrições!$D$2:$D$58,Incrições!F$2:F$58)=0,"",_xlfn.XLOOKUP($C30,Incrições!$D$2:$D$58,Incrições!F$2:F$58)) -> (62)99987-2626 | M30: =IF(_xlfn.XLOOKUP($C30,Incrições!$D$2:$D$58,Incrições!G$2:G$58)=0,"",_xlfn.XLOOKUP($C30,Incrições!$D$2:$D$58,Incrições!G$2:G$58)) -> Montes Claros de Goiás (GO) | N30: =IF(_xlfn.XLOOKUP($C30,Incrições!$D$2:$D$58,Incrições!H$2:H$58)=0,"",_xlfn.XLOOKUP($C30,Incrições!$D$2:$D$58,Incrições!H$2:H$58)) -> CACS-FUNDEB | ... R30: =IF(_xlfn.XLOOKUP($C30,Incrições!$D$2:$D$58,Incrições!L$2:L$58)=0,"",_xlfn.XLOOKUP($C30,Incrições!$D$2:$D$58,Incrições!L$2:L$58)) -> 45924
... A43: 45924.362 | B43: Vânia Aparecida Neves Nogueira | C43: 357.876.668-28 | D43: (66)99931-2629 | E43: Vanianevessilva@hotmail.com | F43: Sim | G43: =IF(_xlfn.XLOOKUP($C43,Incrições!$D$2:$D$58,Incrições!A$2:A$58)=0,"",_xlfn.XLOOKUP($C43,Incrições!$D$2:$D$58,Incrições!A$2:A$58)) -> 45912.664 | H43: =IF(_xlfn.XLOOKUP($C43,Incrições!$D$2:$D$58,Incrições!B$2:B$58)=0,"",_xlfn.XLOOKUP($C43,Incrições!$D$2:$D$58,Incrições!B$2:B$58)) -> vanianevessilva@hotmail.com | I43: =IF(_xlfn.XLOOKUP($C43,Incrições!$D$2:$D$58,Incrições!C$2:C$58)=0,"",_xlfn.XLOOKUP($C43,Incrições!$D$2:$D$58,Incrições!C$2:C$58)) -> Vânia Aparecida Neves Nogueira | J43: =IF(_xlfn.XLOOKUP($C43,Incrições!$D$2:$D$58,Incrições!D$2:D$58)=0,"",_xlfn.XLOOKUP($C43,Incrições!$D$2:$D$58,Incrições!D$2:D$58)) -> 357.876.668-28 | K43: =IF(_xlfn.XLOOKUP($C43,Incrições!$D$2:$D$58,Incrições!E$2:E$58)=0,"",_xlfn.XLOOKUP($C43,Incrições!$D$2:$D$58,Incrições!E$2:E$58)) -> 32775 | L43: =IF(_xlfn.XLOOKUP($C43,Incrições!$D$2:$D$58,Incrições!F$2:F$58)=0,"",_xlfn.XLOOKUP($C43,Incrições!$D$2:$D$58,Incrições!F$2:F$58)) -> (66)99931-2629 | M43: =IF(_xlfn.XLOOKUP($C43,Incrições!$D$2:$D$58,Incrições!G$2:G$58)=0,"",_xlfn.XLOOKUP($C43,Incrições!$D$2:$D$58,Incrições!G$2:G$58)) -> Água Boa (MT) | N43: =IF(_xlfn.XLOOKUP($C43,Incrições!$D$2:$D$58,Incrições!H$2:H$58)=0,"",_xlfn.XLOOKUP($C43,Incrições!$D$2:$D$58,Incrições!H$2:H$58)) -> CACS-FUNDEB | ... R43: =IF(_xlfn.XLOOKUP($C43,Incrições!$D$2:$D$58,Incrições!L$2:L$58)=0,"",_xlfn.XLOOKUP($C43,Incrições!$D$2:$D$58,Incrições!L$2:L$58)) -> 45924
A44: 45924.358 | B44: LUCAS PEREIRA ASSIS | C44: 041.356.531-97 | D44: (66)99971-6956 | E44: lucas_blz_@hotmail.com | F44: Sim | G44: =IF(_xlfn.XLOOKUP($C44,Incrições!$D$2:$D$58,Incrições!A$2:A$58)=0,"",_xlfn.XLOOKUP($C44,Incrições!$D$2:$D$58,Incrições!A$2:A$58)) -> #N/A | H44: =IF(_xlfn.XLOOKUP($C44,Incrições!$D$2:$D$58,Incrições!B$2:B$58)=0,"",_xlfn.XLOOKUP($C44,Incrições!$D$2:$D$58,Incrições!B$2:B$58)) -> #N/A | I44: =IF(_xlfn.XLOOKUP($C44,Incrições!$D$2:$D$58,Incrições!C$2:C$58)=0,"",_xlfn.XLOOKUP($C44,Incrições!$D$2:$D$58,Incrições!C$2:C$58)) -> #N/A | J44: =IF(_xlfn.XLOOKUP($C44,Incrições!$D$2:$D$58,Incrições!D$2:D$58)=0,"",_xlfn.XLOOKUP($C44,Incrições!$D$2:$D$58,Incrições!D$2:D$58)) -> #N/A | K44: =IF(_xlfn.XLOOKUP($C44,Incrições!$D$2:$D$58,Incrições!E$2:E$58)=0,"",_xlfn.XLOOKUP($C44,Incrições!$D$2:$D$58,Incrições!E$2:E$58)) -> #N/A | L44: =IF(_xlfn.XLOOKUP($C44,Incrições!$D$2:$D$58,Incrições!F$2:F$58)=0,"",_xlfn.XLOOKUP($C44,Incrições!$D$2:$D$58,Incrições!F$2:F$58)) -> #N/A | M44: Baliza (GO) | N44: Gestão municipal | O44: =IF(_xlfn.XLOOKUP($C44,Incrições!$D$2:$D$58,Incrições!I$2:I$58)=0,"",_xlfn.XLOOKUP($C44,Incrições!$D$2:$D$58,Incrições!I$2:I$58)) -> #N/A | P44: =IF(_xlfn.XLOOKUP($C44,Incrições!$D$2:$D$58,Incrições!J$2:J$58)=0,"",_xlfn.XLOOKUP($C44,Incrições!$D$2:$D$58,Incrições!J$2:J$58)) -> #N/A | Q44: =IF(_xlfn.XLOOKUP($C44,Incrições!$D$2:$D$58,Incrições!K$2:K$58)=0,"",_xlfn.XLOOKUP($C44,Incrições!$D$2:$D$58,Incrições!K$2:K$58)) -> #N/A | R44: =IF(_xlfn.XLOOKUP($C44,Incrições!$D$2:$D$58,Incrições!L$2:L$58)=0,"",_xlfn.XLOOKUP($C44,Incrições!$D$2:$D$58,Incrições!L$2:L$58)) -> #N/A
A45: 45924.36 | B45: Marcelo Nunes Oliveira | C45: 362.568.541-87 | D45: (66)99207-5555 | E45: Marcelo.oliveira.consultor@gmail.com | F45: Sim | G45: =IF(_xlfn.XLOOKUP($C45,Incrições!$D$2:$D$58,Incrições!A$2:A$58)=0,"",_xlfn.XLOOKUP($C45,Incrições!$D$2:$D$58,Incrições!A$2:A$58)) -> #N/A | H45: =IF(_xlfn.XLOOKUP($C45,Incrições!$D$2:$D$58,Incrições!B$2:B$58)=0,"",_xlfn.XLOOKUP($C45,Incrições!$D$2:$D$58,Incrições!B$2:B$58)) -> #N/A | I45: =IF(_xlfn.XLOOKUP($C45,Incrições!$D$2:$D$58,Incrições!C$2:C$58)=0,"",_xlfn.XLOOKUP($C45,Incrições!$D$2:$D$58,Incrições!C$2:C$58)) -> #N/A | J45: =IF(_xlfn.XLOOKUP($C45,Incrições!$D$2:$D$58,Incrições!D$2:D$58)=0,"",_xlfn.XLOOKUP($C45,Incrições!$D$2:$D$58,Incrições!D$2:D$58)) -> #N/A | K45: =IF(_xlfn.XLOOKUP($C45,Incrições!$D$2:$D$58,Incrições!E$2:E$58)=0,"",_xlfn.XLOOKUP($C45,Incrições!$D$2:$D$58,Incrições!E$2:E$58)) -> #N/A | L45: =IF(_xlfn.XLOOKUP($C45,Incrições!$D$2:$D$58,Incrições!F$2:F$58)=0,"",_xlfn.XLOOKUP($C45,Incrições!$D$2:$D$58,Incrições!F$2:F$58)) -> #N/A | M45: Aragarças (GO) | N45: Gestão municipal | O45: =IF(_xlfn.XLOOKUP($C45,Incrições!$D$2:$D$58,Incrições!I$2:I$58)=0,"",_xlfn.XLOOKUP($C45,Incrições!$D$2:$D$58,Incrições!I$2:I$58)) -> #N/A | P45: =IF(_xlfn.XLOOKUP($C45,Incrições!$D$2:$D$58,Incrições!J$2:J$58)=0,"",_xlfn.XLOOKUP($C45,Incrições!$D$2:$D$58,Incrições!J$2:J$58)) -> #N/A | Q45: =IF(_xlfn.XLOOKUP($C45,Incrições!$D$2:$D$58,Incrições!K$2:K$58)=0,"",_xlfn.XLOOKUP($C45,Incrições!$D$2:$D$58,Incrições!K$2:K$58)) -> #N/A | R45: =IF(_xlfn.XLOOKUP($C45,Incrições!$D$2:$D$58,Incrições!L$2:L$58)=0,"",_xlfn.XLOOKUP($C45,Incrições!$D$2:$D$58,Incrições!L$2:L$58)) -> #N/A
A46: 45924.363 | B46: Denis Rodrigues de Souza | C46: 828.172.351-34 | D46: (66)98465-5624 | E46: denisescolar@hotmail.com | F46: Sim | G46: =IF(_xlfn.XLOOKUP($C46,Incrições!$D$2:$D$58,Incrições!A$2:A$58)=0,"",_xlfn.XLOOKUP($C46,Incrições!$D$2:$D$58,Incrições!A$2:A$58)) -> #N/A | H46: =IF(_xlfn.XLOOKUP($C46,Incrições!$D$2:$D$58,Incrições!B$2:B$58)=0,"",_xlfn.XLOOKUP($C46,Incrições!$D$2:$D$58,Incrições!B$2:B$58)) -> #N/A | I46: =IF(_xlfn.XLOOKUP($C46,Incrições!$D$2:$D$58,Incrições!C$2:C$58)=0,"",_xlfn.XLOOKUP($C46,Incrições!$D$2:$D$58,Incrições!C$2:C$58)) -> #N/A | J46: =IF(_xlfn.XLOOKUP($C46,Incrições!$D$2:$D$58,Incrições!D$2:D$58)=0,"",_xlfn.XLOOKUP($C46,Incrições!$D$2:$D$58,Incrições!D$2:D$58)) -> #N/A | K46: =IF(_xlfn.XLOOKUP($C46,Incrições!$D$2:$D$58,Incrições!E$2:E$58)=0,"",_xlfn.XLOOKUP($C46,Incrições!$D$2:$D$58,Incrições!E$2:E$58)) -> #N/A | L46: =IF(_xlfn.XLOOKUP($C46,Incrições!$D$2:$D$58,Incrições!F$2:F$58)=0,"",_xlfn.XLOOKUP($C46,Incrições!$D$2:$D$58,Incrições!F$2:F$58)) -> #N/A | M46: Porto Alegre do Norte (MT) | N46: Gestão municipal | O46: =IF(_xlfn.XLOOKUP($C46,Incrições!$D$2:$D$58,Incrições!I$2:I$58)=0,"",_xlfn.XLOOKUP($C46,Incrições!$D$2:$D$58,Incrições!I$2:I$58)) -> #N/A | P46: =IF(_xlfn.XLOOKUP($C46,Incrições!$D$2:$D$58,Incrições!J$2:J$58)=0,"",_xlfn.XLOOKUP($C46,Incrições!$D$2:$D$58,Incrições!J$2:J$58)) -> #N/A | Q46: =IF(_xlfn.XLOOKUP($C46,Incrições!$D$2:$D$58,Incrições!K$2:K$58)=0,"",_xlfn.XLOOKUP($C46,Incrições!$D$2:$D$58,Incrições!K$2:K$58)) -> #N/A | R46: =IF(_xlfn.XLOOKUP($C46,Incrições!$D$2:$D$58,Incrições!L$2:L$58)=0,"",_xlfn.XLOOKUP($C46,Incrições!$D$2:$D$58,Incrições!L$2:L$58)) -> #N/A
A47: 45925.349 | B47: Rosiane dos Santos Milhomem | C47: 707.855.201-63 | D47: (66)99688-7811 | E47: rosianemilhomem@gmail.com | F47: Sim | G47: =IF(_xlfn.XLOOKUP($C47,Incrições!$D$2:$D$58,Incrições!A$2:A$58)=0,"",_xlfn.XLOOKUP($C47,Incrições!$D$2:$D$58,Incrições!A$2:A$58)) -> #N/A | H47: =IF(_xlfn.XLOOKUP($C47,Incrições!$D$2:$D$58,Incrições!B$2:B$58)=0,"",_xlfn.XLOOKUP($C47,Incrições!$D$2:$D$58,Incrições!B$2:B$58)) -> #N/A | I47: =IF(_xlfn.XLOOKUP($C47,Incrições!$D$2:$D$58,Incrições!C$2:C$58)=0,"",_xlfn.XLOOKUP($C47,Incrições!$D$2:$D$58,Incrições!C$2:C$58)) -> #N/A | J47: =IF(_xlfn.XLOOKUP($C47,Incrições!$D$2:$D$58,Incrições!D$2:D$58)=0,"",_xlfn.XLOOKUP($C47,Incrições!$D$2:$D$58,Incrições!D$2:D$58)) -> #N/A | K47: =IF(_xlfn.XLOOKUP($C47,Incrições!$D$2:$D$58,Incrições!E$2:E$58)=0,"",_xlfn.XLOOKUP($C47,Incrições!$D$2:$D$58,Incrições!E$2:E$58)) -> #N/A | L47: =IF(_xlfn.XLOOKUP($C47,Incrições!$D$2:$D$58,Incrições!F$2:F$58)=0,"",_xlfn.XLOOKUP($C47,Incrições!$D$2:$D$58,Incrições!F$2:F$58)) -> #N/A | M47: São Félix do Araguaia (MT) | N47: Gestão municipal | O47: =IF(_xlfn.XLOOKUP($C47,Incrições!$D$2:$D$58,Incrições!I$2:I$58)=0,"",_xlfn.XLOOKUP($C47,Incrições!$D$2:$D$58,Incrições!I$2:I$58)) -> #N/A | P47: =IF(_xlfn.XLOOKUP($C47,Incrições!$D$2:$D$58,Incrições!J$2:J$58)=0,"",_xlfn.XLOOKUP($C47,Incrições!$D$2:$D$58,Incrições!J$2:J$58)) -> #N/A | Q47: =IF(_xlfn.XLOOKUP($C47,Incrições!$D$2:$D$58,Incrições!K$2:K$58)=0,"",_xlfn.XLOOKUP($C47,Incrições!$D$2:$D$58,Incrições!K$2:K$58)) -> #N/A | R47: =IF(_xlfn.XLOOKUP($C47,Incrições!$D$2:$D$58,Incrições!L$2:L$58)=0,"",_xlfn.XLOOKUP($C47,Incrições!$D$2:$D$58,Incrições!L$2:L$58)) -> #N/A
A48: 45925.354 | B48: Luciano Carvalho da Silva | C48: 051.765.051-77 | D48: (66)99264-4006 | E48: luciano.artros@gmail.com | F48: Sim | G48: =IF(_xlfn.XLOOKUP($C48,Incrições!$D$2:$D$58,Incrições!A$2:A$58)=0,"",_xlfn.XLOOKUP($C48,Incrições!$D$2:$D$58,Incrições!A$2:A$58)) -> #N/A | H48: =IF(_xlfn.XLOOKUP($C48,Incrições!$D$2:$D$58,Incrições!B$2:B$58)=0,"",_xlfn.XLOOKUP($C48,Incrições!$D$2:$D$58,Incrições!B$2:B$58)) -> #N/A | I48: =IF(_xlfn.XLOOKUP($C48,Incrições!$D$2:$D$58,Incrições!C$2:C$58)=0,"",_xlfn.XLOOKUP($C48,Incrições!$D$2:$D$58,Incrições!C$2:C$58)) -> #N/A | J48: =IF(_xlfn.XLOOKUP($C48,Incrições!$D$2:$D$58,Incrições!D$2:D$58)=0,"",_xlfn.XLOOKUP($C48,Incrições!$D$2:$D$58,Incrições!D$2:D$58)) -> #N/A | K48: =IF(_xlfn.XLOOKUP($C48,Incrições!$D$2:$D$58,Incrições!E$2:E$58)=0,"",_xlfn.XLOOKUP($C48,Incrições!$D$2:$D$58,Incrições!E$2:E$58)) -> #N/A | L48: =IF(_xlfn.XLOOKUP($C48,Incrições!$D$2:$D$58,Incrições!F$2:F$58)=0,"",_xlfn.XLOOKUP($C48,Incrições!$D$2:$D$58,Incrições!F$2:F$58)) -> #N/A | M48: Barra do Garças (MT) | N48: Gestão municipal | O48: =IF(_xlfn.XLOOKUP($C48,Incrições!$D$2:$D$58,Incrições!I$2:I$58)=0,"",_xlfn.XLOOKUP($C48,Incrições!$D$2:$D$58,Incrições!I$2:I$58)) -> #N/A | P48: =IF(_xlfn.XLOOKUP($C48,Incrições!$D$2:$D$58,Incrições!J$2:J$58)=0,"",_xlfn.XLOOKUP($C48,Incrições!$D$2:$D$58,Incrições!J$2:J$58)) -> #N/A | Q48: =IF(_xlfn.XLOOKUP($C48,Incrições!$D$2:$D$58,Incrições!K$2:K$58)=0,"",_xlfn.XLOOKUP($C48,Incrições!$D$2:$D$58,Incrições!K$2:K$58)) -> #N/A | R48: =IF(_xlfn.XLOOKUP($C48,Incrições!$D$2:$D$58,Incrições!L$2:L$58)=0,"",_xlfn.XLOOKUP($C48,Incrições!$D$2:$D$58,Incrições!L$2:L$58)) -> #N/A
A49: 45925.357 | B49: Ideman Celestino da Silva | C49: 495.960.551-00 | D49: (66)98424-5179 | E49: idemarseletino@gmail.com | F49: Sim | G49: =IF(_xlfn.XLOOKUP($C49,Incrições!$D$2:$D$58,Incrições!A$2:A$58)=0,"",_xlfn.XLOOKUP($C49,Incrições!$D$2:$D$58,Incrições!A$2:A$58)) -> #N/A | H49: =IF(_xlfn.XLOOKUP($C49,Incrições!$D$2:$D$58,Incrições!B$2:B$58)=0,"",_xlfn.XLOOKUP($C49,Incrições!$D$2:$D$58,Incrições!B$2:B$58)) -> #N/A | I49: =IF(_xlfn.XLOOKUP($C49,Incrições!$D$2:$D$58,Incrições!C$2:C$58)=0,"",_xlfn.XLOOKUP($C49,Incrições!$D$2:$D$58,Incrições!C$2:C$58)) -> #N/A | J49: =IF(_xlfn.XLOOKUP($C49,Incrições!$D$2:$D$58,Incrições!D$2:D$58)=0,"",_xlfn.XLOOKUP($C49,Incrições!$D$2:$D$58,Incrições!D$2:D$58)) -> #N/A | K49: =IF(_xlfn.XLOOKUP($C49,Incrições!$D$2:$D$58,Incrições!E$2:E$58)=0,"",_xlfn.XLOOKUP($C49,Incrições!$D$2:$D$58,Incrições!E$2:E$58)) -> #N/A | L49: =IF(_xlfn.XLOOKUP($C49,Incrições!$D$2:$D$58,Incrições!F$2:F$58)=0,"",_xlfn.XLOOKUP($C49,Incrições!$D$2:$D$58,Incrições!F$2:F$58)) -> #N/A | M49: São Félix do Araguaia (MT) | N49: Gestão municipal | O49: =IF(_xlfn.XLOOKUP($C49,Incrições!$D$2:$D$58,Incrições!I$2:I$58)=0,"",_xlfn.XLOOKUP($C49,Incrições!$D$2:$D$58,Incrições!I$2:I$58)) -> #N/A | P49: =IF(_xlfn.XLOOKUP($C49,Incrições!$D$2:$D$58,Incrições!J$2:J$58)=0,"",_xlfn.XLOOKUP($C49,Incrições!$D$2:$D$58,Incrições!J$2:J$58)) -> #N/A | Q49: =IF(_xlfn.XLOOKUP($C49,Incrições!$D$2:$D$58,Incrições!K$2:K$58)=0,"",_xlfn.XLOOKUP($C49,Incrições!$D$2:$D$58,Incrições!K$2:K$58)) -> #N/A | R49: =IF(_xlfn.XLOOKUP($C49,Incrições!$D$2:$D$58,Incrições!L$2:L$58)=0,"",_xlfn.XLOOKUP($C49,Incrições!$D$2:$D$58,Incrições!L$2:L$58)) -> #N/A

Sheet Incrições
A1: Carimbo de data/hora | B1: Endereço de e-mail | C1: Nome Completo: | D1: CPF | E1: Data de Nascimento | F1: Telefone (XX)XXXXX-XXXX | G1: Município que representa: | H1: Você faz parte do: | I1: Que cargo você ocupa na gestão municipal? | J1: Prezado(a) Gestor(a), Se existe algum caso de sucesso da gestão do transporte escolar no seu município, gostaríamos conhecer mais um pouco ao respeito. Por favor, relate de forma sucinta o caso de sucesso no espaço a seguir: | K1: Que cargo você ocupa no CACS-FUNDEB? | L1: Dia
A2: 45910.6 | B2: moisesco2009@gmail.com | C2: Moises Correia de Oliveira | D2: 001.805.551-62 | E2: 30577 | F2: (66)98452-0550 | G2: Nova Xavantina (MT) | H2: Gestão municipal | I2: Divisão de Manutenção da Frota | L2: 45925
A3: 45908.469 | B3: marcosrachid93@gmail.com | C3: Marcos Luiz de Jesus Silva Rachid | D3: 002.145.951-70 | E3: 31275 | F3: (66)98426-3841 | G3: São Félix do Araguaia (MT) | H3: CACS-FUNDEB | K3: Vice Presidente | L3: 45925
A4: 45908.474 | B4: marcosrachid93@gmail.com | C4: Marcos Luiz de Jesus Silva Rachid | D4: 002.145.951-70 | E4: 31275 | F4: (66)99979-9371 | G4: São Félix do Araguaia (MT) | H4: CACS-FUNDEB | K4: Vice presidente | L4: 45925
A5: 45916.682 | B5: Wecton.gomes@gmail.com | C5: Wecton Ramos Gomes | D5: 002.528.391-02 | E5: 30535 | F5: (66)99654-9895 | G5: Querência (MT) | H5: Gestão municipal | I5: coordenador de transporte escolar | L5: 45924
A6: 45925.358 | B6: josimeire_quimica2011@hotmail.com | C6: Josimeire de Souza Ramos Resende | D6: 004.763.191-02 | E6: 30616 | F6: (66)98433-8186 | G6: Canabrava do Norte (MT) | H6: Gestão municipal | I6: Secretária Municipal de Educação | L6: 45925
A7: 45908.654 | B7: rosane.cacs@canarana.edu.mt.gov.br | C7: Rosane Fries | D7: 005.341.921-90 | E7: 29948 | F7: (66)99611-2019 | G7: Canarana (MT) | H7: CACS-FUNDEB | K7: Secretaria | L7: 45924
A8: 45908.479 | B8: americoandreia48@gmail.com | C8: Andreia Arruda Américo | D8: 009.151.451-70 | E8: 30150 | F8: (66)98426-3841 | G8: São Félix do Araguaia (MT) | H8: Gestão municipal | I8: Técnica Administrativa do Transporte Escolar | L8: 45925
A9: 45910.576 | B9: elisabeteherrmann@gmail.com | C9: Elisabete Rosália Herrmann Brito | D9: 009.756.161-45 | E9: 31291 | F9: (66)98425-1993 | G9: Vila Rica (MT) | H9: CACS-FUNDEB | K9: Membro | L9: 45925
A10: 45912.518 | B10: 999214662abc@gmail.com | C10: João Paulo de Sousa | D10: 011.848.541-57 | E10: 29917 | F10: (66)98432-9186 | G10: Água Boa (MT) | H10: Gestão municipal | I10: Gerente Transporte Escolar | J10: Fazer um transporte com qualidade mediante a lei | L10: 45924
