Workbook

Sheet P
A1: Carimbo de data/hora | B1: Endereço de e-mail | C1: Nome Completo: | D1: CPF | E1: Você já está inscrito no Curso de Capacitação em Transporte Escolar? | F1: Data de Nascimento | G1: Telefone (XX)XXXXX-XXXX | H1: Município que representa: | I1: Você faz parte do: | J1: Que cargo você ocupa na gestão municipal? | K1: Prezado(a) Gestor(a), Se existe algum caso de sucesso da gestão do transporte escolar no seu município, gostaríamos conhecer mais um pouco ao respeito. Por favor, relate de forma sucinta o caso de sucesso no espaço a seguir: | L1: Que cargo você ocupa no CACS-FUNDEB? | M1: Cidade | N1: Função
A2: 45749.406 | B2: geigyson@gmail.com | C2: Geigyson Mendonça Ribeiro | D2: 003.625.511-46 | E2: Não | F2: 30697 | G2: (67)9689-2918 | H2: Caarapó | I2: Gestão municipal | J2: Instrutor de Informática | M2: Caarapó | N2: Gestão municipal | O2: 0
A3: 45750.41 | B3: adalbertohonorato@hotmail.com | C3: Adalberto Honorato | D3: 015.174.281-22 | E3: Não | F3: 31509 | G3: (67)99614-9223 | H3: Nova Alvorada do Sul | I3: CACS-FUNDEB | L3: Membro Fundeb | M3: Nova Alvorada do Sul | N3: CACS-FUNDEB | O3: 0
A4: 45749.423 | B4: clariceeducacaof2@gmail.com | C4: Clarice de Almeida Faria | D4: 018.097.781-40 | E4: Não | F4: 31200 | G4: (67)99870-7697 | H4: Paraíso das Águas | I4: Gestão municipal | J4: Chefe da Divisão do transporte escolar | M4: Paraíso das Águas | N4: Gestão municipal | O4: 0
A5: 45749.464 | B5: anapedrodugordo12@gmail.com | C5: Ana Cecília Santos Oliveira | D5: 022.800.451-92 | E5: Não | F5: 31610 | G5: (67) 99901-8177 | H5: Douradina | I5: Gestão municipal | J5: Conselheira Tutelar | M5: Douradina | N5: Gestão municipal | O5: 0
A6: 45749.424 | B6: geovaniamachadolemos@gmail.com | C6: Geovania Machado Lemos | D6: 023.432.791-01 | E6: Não | F6: 31512 | G6: (67)99914-3233 | H6: Paraíso das Águas | I6: Gestão municipal | J6: Diretora de apoio administrativo | M6: Paraíso das Águas | N6: Gestão municipal | O6: 0
A7: 45749.498 | B7: rafaelfilho.sofia@gmail.com | C7: Rafael Aparecido da Silva Bezerra | D7: 028.916.671-31 | E7: Não | F7: 32475 | G7: (67) 98182-7265 | H7: Bataguassu | I7: Gestão municipal | J7: Coordenador do Transporte Escolar | M7: Bataguassu | N7: Gestão municipal | O7: 0
A8: 45750.544 | B8: julianimalu@gmail.com | C8: Juliani Cristini Sieve | D8: 045.073.871-08 | E8: Não | F8: 34332 | G8: (67)98119-9686 | H8: Novo Horizonte do Sul | I8: CACS-FUNDEB | L8: Represetante de Pais | M8: Novo Horizonte do Sul | N8: CACS-FUNDEB | O8: 0
A9: 45749.496 | B9: fayane.m@hotmail.com | C9: Fayane Montenegro Gonçalves Paz | D9: 048.862.981-09 | E9: Não | F9: 34577 | G9: (67) 99684-8202 | H9: Douradina | I9: Gestão municipal | J9: Técnica administrativa | M9: Douradina | N9: Gestão municipal | O9: 0
A10: 45750.398 | B10: augustocesarinformarica@gmail.com | C10: Augusto César Henriques | D10: 080.397.776-07 | E10: Não | F10: 31405 | G10: (67) 998271129 | H10: Maracaju | I10: Gestão municipal | J10: Técnico de Prestação de contas do transporte escolar | M10: Maracaju | N10: Gestão municipal | O10: 0
A11: 45750.4 | B11: danimedina826@gmail.com | C11: Daniela Medina | D11: 083.222.581-94 | E11: Não | F11: 36569 | G11: (67) 998523934 | H11: Laguna Carapã | I11: Gestão municipal | J11: Técnica | M11: Laguna Carapã | N11: Gestão municipal | O11: 0
A12: 45750.4 | B12: dr.diego.ribeiro25@gmail.com | C12: Diego Ribeiro | D12: 355.073.268-60 | E12: Não | F12: 31913 | G12: (67) 991391611 | H12: Laguna Carapã | I12: CACS-FUNDEB | L12: Presidente Fundeb | M12: Laguna Carapã | N12: CACS-FUNDEB | O12: 0
A13: 45749.416 | B13: costa.dema2409@gmail.com | C13: Ademir da Silva Costa | D13: 500.851.311-72 | E13: Não | F13: 25470 | G13: (67)99958-4558 | H13: Glória de Dourados | I13: CACS-FUNDEB | L13: Vice presidente | M13: Glória de Dourados | N13: CACS-FUNDEB | O13: 0
A14: 45749.418 | B14: gislenemfarias@hotmail.com | C14: Gislene Aparecida Micuinha Farias | D14: 519.164.361-53 | E14: Não | F14: 25676 | G14: (67)99963-8701 | H14: Coronel Sapucaia | I14: Gestão municipal | J14: Prestação de contas | K14: Não tem | M14: Coronel Sapucaia | N14: Gestão municipal | O14: 0
A15: 45750.54 | B15: paulo.cesar.75@hotmail.com | C15: Paulo Cesar Mota dos Santos | D15: 560.189.911-87 | E15: Não | F15: 27486 | G15: (67)99624-4128 | H15: Sete Quedas | I15: Gestão municipal | J15: Secretário da Educação | M15: Sete Quedas | N15: Gestão municipal | O15: 0
A16: 45749.413 | B16: valderene13@gmail.com | C16: Valderene Ferreira de Alencar | D16: 582.163.831-34 | E16: Não | F16: 26355 | G16: (67)99997-7213 | H16: Dourados | I16: Gestão municipal | J16: Assessoria da Deputada Estadual Gleice Jane Barbosa | K16: Não conheço | M16: Dourados | N16: Gestão municipal | O16: 0
A17: 45749.41 | B17: dpfedufisica@hotmail.com | C17: Danillo Petinari Ferratto | D17: 654.708.931-20 | E17: Não | F17: 28376 | G17: (67)99677-9393 | H17: Itaporã | I17: Gestão municipal | J17: Técnico departamento de transporte escolar | K17: Logística das rotas | M17: Itaporã | N17: Gestão municipal | O17: 0
A18: 45750.402 | B18: andresenize@hotmail.com | C18: André de Souza Mattos | D18: 813.198.431-15 | E18: Não | F18: 28771 | G18: (67)98131-5635 | H18: Japorã | I18: CACS-FUNDEB | L18: Presidente | M18: Japorã | N18: CACS-FUNDEB | O18: 0
A19: 45750.545 | B19: anderson-2511@hotmail.com | C19: Odirlei Ferreira Calixto | D19: 956.340.371-15 | E19: Não | F19: 28811 | G19: (67)98117-7795 | H19: Novo Horizonte do Sul | I19: Gestão municipal | J19: Motorista | M19: Novo Horizonte do Sul | N19: Gestão municipal | O19: 0
A20: 45749.421 | B20: benilson.or.oliveira@hotmail.com | C20: Benilson Ormandes de Oliveira | D20: 959.818.611-34 | E20: Não | F20: 30211 | G20: (67)99883-1574 | H20: Paraíso das Águas | I20: Gestão municipal | J20: Assessor técnico | K20: Iniciei no setor este ano gostaria de participar de mais capacitações | M20: Paraíso das Águas | N20: Gestão municipal | O20: 0
A21: 45749.599 | B21: maria_aigustha@hormail.com | C21: Maria Augustha Espíndola Domingues | D21: 000.249.231-84 | E21: Sim | M21: Dourados | N21: CACS-FUNDEB | O21: 0
A22: 45750.399 | B22: valdineipavanelli@hotmail.com | C22: Valdinei da Silva Pavanelli | D22: 000.371.471-37 | E22: Sim | M22: Japorã | N22: Gestão municipal | O22: 0
A23: 45749.406 | B23: fv747993@gmail.com | C23: José Fernando Vieira da Silva | D23: 005.338.441-50 | E23: Sim | M23: Angélica | N23: Gestão municipal | O23: 0
A24: 45750.406 | B24: marisantin6@gmail.com | C24: Marilete Santin | D24: 009.602.231-00 | E24: Sim | M24: Rio Brilhante | N24: CACS-FUNDEB | O24: 0
A25: 45750.407 | B25: Transporteescolar@novaalvoradadosul.ms.gov.br | C25: Ozeias Morais da Silva | D25: 014.985.871-00 | E25: Sim | M25: Nova Alvorada do Sul | N25: Gestão municipal | O25: 0
A26: 45749.471 | B26: smec2018@outlook.com | C26: Adriana Ramos da Silva | D26: 015.884.291-05 | E26: Sim | M26: Batayporã | N26: Gestão municipal | O26: 0
A27: 45750.401 | B27: marcio021186@gmail.com | C27: Marcio de Souza Santos | D27: 018.880.441-28 | E27: Sim | M27: Taquarussu | N27: Gestão municipal | O27: 0
A28: 45749.469 | B28: vanderleifreitas722@gmail.com | C28: Vanderlei de Freitas Santos | D28: 019.226.361-77 | E28: Sim | M28: Batayporã | N28: CACS-FUNDEB | O28: 0
A29: 45749.406 | B29: ricardosm2002@hotmail.com | C29: Ricardo Souza Marchini | D29: 022.616.841-77 | E29: Sim | M29: Angélica | N29: Gestão municipal | O29: 0
A30: 45750.395 | B30: jaque_hernacki@hotmail.com | C30: Jaqueline Hernacki | D30: 023.145.741-33 | E30: Sim | M30: Paranhos | N30: Gestão municipal | O30: 0
A31: 45749.44 | B31: narahbraguini@gmail.com | C31: Nara Henrique Braguini | D31: 023.395.351-58 | E31: Sim | M31: Ivinhema | N31: Gestão municipal | O31: 0
A32: 45749.399 | B32: prof_jcarvalho@outlook.com | C32: Jucimar Carvalho Chaves | D32: 031.051.231-05 | E32: Sim | M32: Coronel Sapucaia | N32: CACS-FUNDEB | O32: 0
... A92: 45749.4 | B92: cleberfaria5552@gmail.com | C92: Cleber Roza de Faria | D92: 982.073.261-15 | E92: Sim | M92: Deodápolis | N92: Gestão municipal | O92: 0
A93: 45750.54 | B93: criswentzprestes@outlook.com | C93: Crislaine Wentz Ferreira | D93: 985.453.291-72 | E93: Sim | O93: 0
A95: 45749.409 | B95: anapedrodugordo12@gmail.com | C95: Ana Cecília Santos Oliveira | D95: 022.800.451-92 | E95: Não | F95: 31610 | G95: (67)99901-8178 | H95: Douradina | I95: Gestão municipal | J95: Conselheira Tutelar | M95: Douradina | N95: Gestão municipal | O95: 1
A96: 45749.459 | B96: marcosantoniokol17@gmail.com | C96: Marcos Antônio Kol Rudes | D96: 088.101.191-69 | E96: Sim | M96: Aral Moreira | N96: Gestão municipal | O96: 1
A97: 45749.398 | B97: camilosanches2247@hotmail.com | C97: José Camilo Sanches | D97: 312.780.271-49 | E97: Sim | M97: Eldorado | N97: Gestão municipal | O97: 1
A98: 45749.405 | B98: camilosanches2247@hotmail.com | C98: José Camilo Sanches | D98: 312.780.271-49 | E98: Sim | M98: Eldorado | N98: Gestão municipal | O98: 1
A99: 45749.383 | B99: professorasuelli@gmail.com | C99: Sueli Menezes da Silva | D99: 480.712.501-04 | E99: Sim | M99: Glória de Dourados | N99: Gestão municipal | O99: 1
A100: 45749.405 | B100: professorasuelli@gmail.com | C100: Sueli Menezes da Silva | D100: 480.712.501-04 | E100: Sim | M100: Glória de Dourados | N100: Gestão municipal | O100: 1
...

Sheet Certificado
A1: CPF | B1: Nome | C1: E-mail | D1: Data | E1: Cidade | F1: Função | H1: Data
A2: 319.591.219-87 | B2: =LOOKUP(A2,Inscritos!$E$2:$E$110,Inscritos!$D$2:$D$110) -> Osmar Aparecido Delvecchio | C2: =LOOKUP(A2,Inscritos!$E$2:$E$110,Inscritos!$C$2:$C$110) -> profosmar@hotmail.com | D2: =LOOKUP(A2,Inscritos!$E$2:$E$110,Inscritos!$F$2:$F$110) -> 21421 | E2: =LOOKUP(A2,Inscritos!$E$2:$E$110,Inscritos!$H$2:$H$110) -> Amambai | F2: =LOOKUP(A2,Inscritos!$E$2:$E$110,Inscritos!$I$2:$I$110) -> CACS-FUNDEB | G2: Matheus | H2: =LOOKUP(A2,Inscritos!$E$2:$E$110,Inscritos!$M$2:$M$110) -> 45749
A3: 372.774.131-72 | B3: =LOOKUP(A3,Inscritos!$E$2:$E$110,Inscritos!$D$2:$D$110) -> Valdemar Antônio de Oliveira | C3: =LOOKUP(A3,Inscritos!$E$2:$E$110,Inscritos!$C$2:$C$110) -> valdemarantonio5@hotmail.com | D3: =LOOKUP(A3,Inscritos!$E$2:$E$110,Inscritos!$F$2:$F$110) -> 24597 | E3: =LOOKUP(A3,Inscritos!$E$2:$E$110,Inscritos!$H$2:$H$110) -> Amambai | F3: =LOOKUP(A3,Inscritos!$E$2:$E$110,Inscritos!$I$2:$I$110) -> Gestão municipal | G3: Matheus | H3: =LOOKUP(A3,Inscritos!$E$2:$E$110,Inscritos!$M$2:$M$110) -> 45749
A4: 830.554.871-68 | B4: =LOOKUP(A4,Inscritos!$E$2:$E$110,Inscritos!$D$2:$D$110) -> Edinaldo Silva | C4: =LOOKUP(A4,Inscritos!$E$2:$E$110,Inscritos!$C$2:$C$110) -> edinaldo_s_silva@hotmail.com | D4: =LOOKUP(A4,Inscritos!$E$2:$E$110,Inscritos!$F$2:$F$110) -> 28265 | E4: =LOOKUP(A4,Inscritos!$E$2:$E$110,Inscritos!$H$2:$H$110) -> Amambai | F4: =LOOKUP(A4,Inscritos!$E$2:$E$110,Inscritos!$I$2:$I$110) -> CACS-FUNDEB | G4: Matheus | H4: =LOOKUP(A4,Inscritos!$E$2:$E$110,Inscritos!$M$2:$M$110) -> 45749
A5: 971.277.281-00 | B5: =LOOKUP(A5,Inscritos!$E$2:$E$110,Inscritos!$D$2:$D$110) -> Wender Luiz Farias Garai | C5: =LOOKUP(A5,Inscritos!$E$2:$E$110,Inscritos!$C$2:$C$110) -> transporte.escolar.amambai@hotmail.com | D5: =LOOKUP(A5,Inscritos!$E$2:$E$110,Inscritos!$F$2:$F$110) -> 29614 | E5: =LOOKUP(A5,Inscritos!$E$2:$E$110,Inscritos!$H$2:$H$110) -> Amambai | F5: =LOOKUP(A5,Inscritos!$E$2:$E$110,Inscritos!$I$2:$I$110) -> CACS-FUNDEB | G5: Matheus | H5: =LOOKUP(A5,Inscritos!$E$2:$E$110,Inscritos!$M$2:$M$110) -> 45749
A6: 554.765.201-63 | B6: =LOOKUP(A6,Inscritos!$E$2:$E$110,Inscritos!$D$2:$D$110) -> EDSON UMBELINO | C6: =LOOKUP(A6,Inscritos!$E$2:$E$110,Inscritos!$C$2:$C$110) -> osmair_garcia@hotmail.com | D6: =LOOKUP(A6,Inscritos!$E$2:$E$110,Inscritos!$F$2:$F$110) -> 21306 | E6: =LOOKUP(A6,Inscritos!$E$2:$E$110,Inscritos!$H$2:$H$110) -> Anaurilândia | F6: =LOOKUP(A6,Inscritos!$E$2:$E$110,Inscritos!$I$2:$I$110) -> Gestão municipal | G6: Matheus | H6: =LOOKUP(A6,Inscritos!$E$2:$E$110,Inscritos!$M$2:$M$110) -> 45749
A7: 796.398.951-72 | B7: =LOOKUP(A7,Inscritos!$E$2:$E$110,Inscritos!$D$2:$D$110) -> OSMAIR ALVES GARCIA | C7: =LOOKUP(A7,Inscritos!$E$2:$E$110,Inscritos!$C$2:$C$110) -> osmair_garcia@hotmail.com | D7: =LOOKUP(A7,Inscritos!$E$2:$E$110,Inscritos!$F$2:$F$110) -> 28554 | E7: =LOOKUP(A7,Inscritos!$E$2:$E$110,Inscritos!$H$2:$H$110) -> Anaurilândia | F7: =LOOKUP(A7,Inscritos!$E$2:$E$110,Inscritos!$I$2:$I$110) -> Gestão municipal | G7: Matheus | H7: =LOOKUP(A7,Inscritos!$E$2:$E$110,Inscritos!$M$2:$M$110) -> 45749
A8: 005.338.441-50 | B8: =LOOKUP(A8,Inscritos!$E$2:$E$110,Inscritos!$D$2:$D$110) -> José Fernando Vieira da Silva | C8: =LOOKUP(A8,Inscritos!$E$2:$E$110,Inscritos!$C$2:$C$110) -> fv747993@gmail.com | D8: =LOOKUP(A8,Inscritos!$E$2:$E$110,Inscritos!$F$2:$F$110) -> 30850 | E8: =LOOKUP(A8,Inscritos!$E$2:$E$110,Inscritos!$H$2:$H$110) -> Angélica | F8: =LOOKUP(A8,Inscritos!$E$2:$E$110,Inscritos!$I$2:$I$110) -> Gestão municipal | G8: Matheus | H8: =LOOKUP(A8,Inscritos!$E$2:$E$110,Inscritos!$M$2:$M$110) -> 45749
A9: 022.616.841-77 | B9: =LOOKUP(A9,Inscritos!$E$2:$E$110,Inscritos!$D$2:$D$110) -> RICARDO SOUZA MARCHINI | C9: =LOOKUP(A9,Inscritos!$E$2:$E$110,Inscritos!$C$2:$C$110) -> ricardosm2002@hotmail.com | D9: =LOOKUP(A9,Inscritos!$E$2:$E$110,Inscritos!$F$2:$F$110) -> 37344 | E9: =LOOKUP(A9,Inscritos!$E$2:$E$110,Inscritos!$H$2:$H$110) -> Angélica | F9: =LOOKUP(A9,Inscritos!$E$2:$E$110,Inscritos!$I$2:$I$110) -> Gestão municipal | G9: Matheus | H9: =LOOKUP(A9,Inscritos!$E$2:$E$110,Inscritos!$M$2:$M$110) -> 45749
A10: 088.101.191-69 | B10: =LOOKUP(A10,Inscritos!$E$2:$E$110,Inscritos!$D$2:$D$110) -> Marcos Antônio Kol Rudes | C10: =LOOKUP(A10,Inscritos!$E$2:$E$110,Inscritos!$C$2:$C$110) -> marcosantoniokol17@gmail.com | D10: =LOOKUP(A10,Inscritos!$E$2:$E$110,Inscritos!$F$2:$F$110) -> 52961 | E10: =LOOKUP(A10,Inscritos!$E$2:$E$110,Inscritos!$H$2:$H$110) -> Aral Moreira | F10: =LOOKUP(A10,Inscritos!$E$2:$E$110,Inscritos!$I$2:$I$110) -> Gestão municipal | G10: Matheus | H10: =LOOKUP(A10,Inscritos!$E$2:$E$110,Inscritos!$M$2:$M$110) -> 45749
A11: 906.974.991-20 | B11: =LOOKUP(A11,Inscritos!$E$2:$E$110,Inscritos!$D$2:$D$110) -> Marta Vieira Leite Rigon | C11: =LOOKUP(A11,Inscritos!$E$2:$E$110,Inscritos!$C$2:$C$110) -> martavlrigon@gmail.com | D11: =LOOKUP(A11,Inscritos!$E$2:$E$110,Inscritos!$F$2:$F$110) -> 29554 | E11: =LOOKUP(A11,Inscritos!$E$2:$E$110,Inscritos!$H$2:$H$110) -> Aral Moreira | F11: =LOOKUP(A11,Inscritos!$E$2:$E$110,Inscritos!$I$2:$I$110) -> Gestão municipal | G11: Matheus | H11: =LOOKUP(A11,Inscritos!$E$2:$E$110,Inscritos!$M$2:$M$110) -> 45749
A12: 365.252.431-49 | B12: =LOOKUP(A12,Inscritos!$E$2:$E$110,Inscritos!$D$2:$D$110) -> Alcenir Rodrigues de Lima | C12: =LOOKUP(A12,Inscritos!$E$2:$E$110,Inscritos!$C$2:$C$110) -> alcenirlima2025semec@gmail.com | D12: =LOOKUP(A12,Inscritos!$E$2:$E$110,Inscritos!$F$2:$F$110) -> 24785 | E12: =LOOKUP(A12,Inscritos!$E$2:$E$110,Inscritos!$H$2:$H$110) -> Bataguassu | F12: =LOOKUP(A12,Inscritos!$E$2:$E$110,Inscritos!$I$2:$I$110) -> Gestão municipal | G12: Matheus | H12: =LOOKUP(A12,Inscritos!$E$2:$E$110,Inscritos!$M$2:$M$110) -> 45749
A13: 015.884.291-05 | B13: =LOOKUP(A13,Inscritos!$E$2:$E$110,Inscritos!$D$2:$D$110) -> Adriana Ramos da Silva | C13: =LOOKUP(A13,Inscritos!$E$2:$E$110,Inscritos!$C$2:$C$110) -> smec2018@outlook.com | D13: =LOOKUP(A13,Inscritos!$E$2:$E$110,Inscritos!$F$2:$F$110) -> 31964 | E13: =LOOKUP(A13,Inscritos!$E$2:$E$110,Inscritos!$H$2:$H$110) -> Batayporã | F13: =LOOKUP(A13,Inscritos!$E$2:$E$110,Inscritos!$I$2:$I$110) -> Gestão municipal | G13: Matheus | H13: =LOOKUP(A13,Inscritos!$E$2:$E$110,Inscritos!$M$2:$M$110) -> 45749
... A93: 956.340.371-15 | B93: =LOOKUP(A93,Inscritos!$E$2:$E$110,Inscritos!$D$2:$D$110) -> Odirlei Ferreira Calixto | C93: =LOOKUP(A93,Inscritos!$E$2:$E$110,Inscritos!$C$2:$C$110) -> anderson-2511@hotmail.com | D93: =LOOKUP(A93,Inscritos!$E$2:$E$110,Inscritos!$F$2:$F$110) -> 28811 | E93: =LOOKUP(A93,Inscritos!$E$2:$E$110,Inscritos!$H$2:$H$110) -> Novo Horizonte do Sul | F93: =LOOKUP(A93,Inscritos!$E$2:$E$110,Inscritos!$I$2:$I$110) -> Gestão municipal | G93: Robinson | H93: =LOOKUP(A93,Inscritos!$E$2:$E$110,Inscritos!$M$2:$M$110) -> 45750.545

Sheet Presentes
A1: XXX | B1: Carimbo de data/hora | C1: Endereço de e-mail | D1: Nome Completo: | E1: CPF | F1: Você já está inscrito no Curso de Capacitação em Transporte Escolar? | G1: Cidade | H1: Função
B2: 45749.407 | C2: profosmar@hotmail.com | D2: Osmar Aparecido Delvecchio | E2: 319.591.219-87 | G2: =LOOKUP(E2,Inscritos!$E$2:$E$110,Inscritos!$H$2:$H$110) -> Amambai | H2: =LOOKUP(E2,Inscritos!$E$2:$E$110,Inscritos!$I$2:$I$110) -> CACS-FUNDEB | I2: =LOOKUP(E2,Inscritos!$E$2:$E$110,Inscritos!$E$2:$E$110) -> 319.591.219-87
B3: 45749.413 | C3: valdemarantonio5@hotmail.com | D3: Valdemar Antônio de Oliveira | E3: 372.774.131-72 | G3: =LOOKUP(E3,Inscritos!$E$2:$E$110,Inscritos!$H$2:$H$110) -> Amambai | H3: =LOOKUP(E3,Inscritos!$E$2:$E$110,Inscritos!$I$2:$I$110) -> Gestão municipal | I3: =LOOKUP(E3,Inscritos!$E$2:$E$110,Inscritos!$E$2:$E$110) -> 372.774.131-72
B4: 45749.544 | C4: edinaldo_s_silva@hotmail.com | D4: Edinaldo Silva | E4: 830.554.871-68 | G4: =LOOKUP(E4,Inscritos!$E$2:$E$110,Inscritos!$H$2:$H$110) -> Amambai | H4: =LOOKUP(E4,Inscritos!$E$2:$E$110,Inscritos!$I$2:$I$110) -> CACS-FUNDEB | I4: =LOOKUP(E4,Inscritos!$E$2:$E$110,Inscritos!$E$2:$E$110) -> 830.554.871-68
B5: 45749.409 | C5: garai.wender@gmail.com | D5: Wender Luiz Farias Garai | E5: 971.277.281-00 | G5: =LOOKUP(E5,Inscritos!$E$2:$E$110,Inscritos!$H$2:$H$110) -> Amambai | H5: =LOOKUP(E5,Inscritos!$E$2:$E$110,Inscritos!$I$2:$I$110) -> CACS-FUNDEB | I5: =LOOKUP(E5,Inscritos!$E$2:$E$110,Inscritos!$E$2:$E$110) -> 971.277.281-00
B6: 45749.405 | C6: nenemdaolaria@yahoo.com.br | D6: Edson Umbelino | E6: 554.765.201-63 | G6: =LOOKUP(E6,Inscritos!$E$2:$E$110,Inscritos!$H$2:$H$110) -> Anaurilândia | H6: =LOOKUP(E6,Inscritos!$E$2:$E$110,Inscritos!$I$2:$I$110) -> Gestão municipal | I6: =LOOKUP(E6,Inscritos!$E$2:$E$110,Inscritos!$E$2:$E$110) -> 554.765.201-63
B7: 45749.403 | C7: osmair_garcia@hotmail.com | D7: Osmair Alves Garcia | E7: 796.398.951-72 | G7: =LOOKUP(E7,Inscritos!$E$2:$E$110,Inscritos!$H$2:$H$110) -> Anaurilândia | H7: =LOOKUP(E7,Inscritos!$E$2:$E$110,Inscritos!$I$2:$I$110) -> Gestão municipal | I7: =LOOKUP(E7,Inscritos!$E$2:$E$110,Inscritos!$E$2:$E$110) -> 796.398.951-72
B8: 45749.406 | C8: fv747993@gmail.com | D8: José Fernando Vieira da Silva | E8: 005.338.441-50 | G8: =LOOKUP(E8,Inscritos!$E$2:$E$110,Inscritos!$H$2:$H$110) -> Angélica | H8: =LOOKUP(E8,Inscritos!$E$2:$E$110,Inscritos!$I$2:$I$110) -> Gestão municipal | I8: =LOOKUP(E8,Inscritos!$E$2:$E$110,Inscritos!$E$2:$E$110) -> 005.338.441-50
B9: 45749.406 | C9: ricardosm2002@hotmail.com | D9: Ricardo Souza Marchini | E9: 022.616.841-77 | G9: =LOOKUP(E9,Inscritos!$E$2:$E$110,Inscritos!$H$2:$H$110) -> Angélica | H9: =LOOKUP(E9,Inscritos!$E$2:$E$110,Inscritos!$I$2:$I$110) -> Gestão municipal | I9: =LOOKUP(E9,Inscritos!$E$2:$E$110,Inscritos!$E$2:$E$110) -> 022.616.841-77
B10: 45749.692 | C10: marcosantoniokol17@gmail.com | D10: Marcos Antônio Kol Rudes | E10: 088.101.191-69 | G10: =LOOKUP(E10,Inscritos!$E$2:$E$110,Inscritos!$H$2:$H$110) -> Aral Moreira | H10: =LOOKUP(E10,Inscritos!$E$2:$E$110,Inscritos!$I$2:$I$110) -> Gestão municipal | I10: =LOOKUP(E10,Inscritos!$E$2:$E$110,Inscritos!$E$2:$E$110) -> 088.101.191-69
B11: 45749.693 | C11: martavlrigon@gmail.com | D11: Marta Vieira Leite Rigon | E11: 906.974.991-20 | G11: =LOOKUP(E11,Inscritos!$E$2:$E$110,Inscritos!$H$2:$H$110) -> Aral Moreira | H11: =LOOKUP(E11,Inscritos!$E$2:$E$110,Inscritos!$I$2:$I$110) -> Gestão municipal | I11: =LOOKUP(E11,Inscritos!$E$2:$E$110,Inscritos!$E$2:$E$110) -> 906.974.991-20
B12: 45749.498 | C12: rafaelfilho.sofia@gmail.com | D12: Rafael Aparecido da Silva Bezerra | E12: 028.916.671-31 | G12: =LOOKUP(E12,Inscritos!$E$2:$E$110,Inscritos!$H$2:$H$110) -> Bataguassu | H12: =LOOKUP(E12,Inscritos!$E$2:$E$110,Inscritos!$I$2:$I$110) -> Gestão municipal | I12: =LOOKUP(E12,Inscritos!$E$2:$E$110,Inscritos!$E$2:$E$110) -> 028.916.671-31
B13: 45749.498 | C13: alcenirlima2025semec@gmail.com | D13: Alcenir Rodrigues de Lima | E13: 365.252.431-49 | G13: =LOOKUP(E13,Inscritos!$E$2:$E$110,Inscritos!$H$2:$H$110) -> Bataguassu | H13: =LOOKUP(E13,Inscritos!$E$2:$E$110,Inscritos!$I$2:$I$110) -> Gestão municipal | I13: =LOOKUP(E13,Inscritos!$E$2:$E$110,Inscritos!$E$2:$E$110) -> 365.252.431-49
... B93: 45750.54 | C93: criswentzprestes@outlook.com | D93: Crislaine Wentz Ferreira | E93: 985.453.291-72 | G93: =LOOKUP(E93,Inscritos!$E$2:$E$110,Inscritos!$H$2:$H$110) -> Sete Quedas | H93: =LOOKUP(E93,Inscritos!$E$2:$E$110,Inscritos!$I$2:$I$110) -> CACS-FUNDEB | I93: =LOOKUP(E93,Inscritos!$E$2:$E$110,Inscritos!$E$2:$E$110) -> 985.453.291-72

Sheet INS
A1: Carimbo de data/hora | B1: Endereço de e-mail | C1: Nome Completo: | D1: CPF | E1: Data de Nascimento | F1: Telefone (XX)XXXXX-XXXX | G1: Município que representa: | H1: Você faz parte do: | I1: Que cargo você ocupa na gestão municipal? | J1: Prezado(a) Gestor(a), Se existe algum caso de sucesso da gestão do transporte escolar no seu município, gostaríamos conhecer mais um pouco ao respeito. Por favor, relate de forma sucinta o caso de sucesso no espaço a seguir: | K1: Que cargo você ocupa no CACS-FUNDEB? | L1: Dia
A2: 45742.686 | B2: maria_augustha@hotmail.com | C2: Maria Augustha Espíndola Domingues | D2: 000.249.231-84 | E2: 30191 | F2: (67)99971-2118 | G2: Dourados | H2: CACS-FUNDEB | K2: Conselheira representante secretaria municipal de educação de dourados | L2: 45749 | M2: 0
A3: 45744.338 | B3: valdineipavanelli@hotmail.com | C3: valdinei da silva pavanelli | D3: 000.371.471-37 | E3: 30671 | F3: (67)98140-1864 | G3: Japorã | H3: Gestão municipal | I3: chefe de divisão do transporte escolar | L3: 45750 | M3: 0
A4: 45748.438 | B4: fv747993@gmail.com | C4: José Fernando Vieira da Silva | D4: 005.338.441-50 | E4: 30850 | F4: (67)99225-2689 | G4: Angélica | H4: Gestão municipal | I4: Chefe de Núcleo de Transporte Escolar | L4: 45749 | M4: 0
A5: 45743.476 | B5: marisantin6@gmail.com | C5: Marilete Santin | D5: 009.602.231-00 | E5: 31173 | F5: (67)99954-7035 | G5: Rio Brilhante | H5: CACS-FUNDEB | K5: Representante Escolas do Campo | L5: 45750 | M5: 0
A6: 45737.488 | B6: semecel@jatei.ms.gov.br | C6: THIAGO RODRIGUES DOS REIS | D6: 012.494.461-20 | E6: 31446 | F6: (67)99848-6764 | G6: Jateí | H6: CACS-FUNDEB | K6: MEMBRO | L6: 45750 | M6: 0
A7: 45748.709 | B7: Transporteescolar@novaalvoradadosul.ms.gov.br | C7: Ozeias Morais da Silva | D7: 014.985.871-00 | E7: 31161 | F7: (67)99678-2795 | G7: Nova Alvorada do Sul | H7: Gestão municipal | I7: Coordenador de transporte escolar | L7: 45750 | M7: 0
A8: 45737.402 | B8: smec2018@outlook.com | C8: Adriana Ramos da Silva | D8: 015.884.291-05 | E8: 31964 | F8: (67)99626-6555 | G8: Batayporã | H8: Gestão municipal | I8: Técnica do Transporte Escolar | L8: 45749 | M8: 0
A9: 45748.479 | B9: tania_ruivo@hotmail.com | C9: Tania Aparecida Ruivo da Luz | D9: 017.339.721-29 | E9: 31923 | F9: (67)99253-6974 | G9: Amambai | H9: Gestão municipal | I9: Secretária de Educação | J9: Não temos ni momento | L9: 45749 | M9: 0
A10: 45747.428 | B10: semec@taquarussu.ms.gov.br | C10: Marcio de souza santos | D10: 018.880.441-28 | E10: 31718 | F10: (67)99639-3728 | G10: Taquarussu | H10: Gestão municipal | I10: Diretor do transporte | L10: 45750 | M10: 0
A11: 45748.938 | B11: vanderleifreitas722@gmail.com | C11: Vanderlei de Freitas Santos | D11: 019.226.361-77 | E11: 32384 | F11: (67)99919-6945 | G11: Batayporã | H11: CACS-FUNDEB | K11: Presidente | L11: 45749 | M11: 0
A12: 45748.447 | B12: ricardosm2002@hotmail.com | C12: RICARDO SOUZA MARCHINI | D12: 022.616.841-77 | E12: 37344 | F12: (67)99671-9885 | G12: Angélica | H12: Gestão municipal | I12: CONTADOR | L12: 45749 | M12: 0
A13: 45733.699 | B13: jaque_hernacki@hotmail.com | C13: Jaqueline Hernacki | D13: 023.145.741-33 | E13: 32243 | F13: (67)99962-9226 | G13: Paranhos | H13: Gestão municipal | I13: Tecnica de prestação de contas | L13: 45750 | M13: 0
A14: 45734.474 | B14: narahbraguini@gmail.com | C14: Nara Henrique Braguini | D14: 023.395.351-58 | E14: 32021 | F14: (67)99971-3774 | G14: Ivinhema | H14: Gestão municipal | I14: Coordenadora | L14: 45749 | M14: 0
A15: 45747.523 | B15: prof_jcarvalho@outlook.com | C15: Jucimar Carvalho Chaves | D15: 031.051.231-05 | E15: 32514 | F15: (67)99172-4459 | G15: Coronel Sapucaia | H15: CACS-FUNDEB | K15: Técnico | L15: 45749 | M15: 0
A16: 45740.7 | B16: patricnascimentodasilva@gmail.com | C16: Patric Nascimento da Silva | D16: 032.323.241-85 | E16: 32447 | F16: (67)99935-6261 | G16: Maracaju | H16: CACS-FUNDEB | K16: Diretor de transporte | L16: 45750 | M16: 0
A17: 45736.619 | B17: josilaineneves01@gmail.com | C17: JOSILÂINE NEVES DA SILVA | D17: 032.679.841-22 | E17: 32569 | F17: (67)99101-5042 | G17: Caarapó | H17: Gestão municipal | I17: CHEFE DE DEPARTAMENTO DO TRANSPORTE ESCOLAR | L17: 45749 | M17: 0
A18: 45749.706 | B18: simaoschuh1@gmail.com | C18: Simão Sirineu Schuh Dias | D18: 033.593.471-45 | E18: 33019 | F18: (67)99627-7244 | G18: Sete Quedas | H18: CACS-FUNDEB | K18: Representante de pais e alunos | L18: 45750 | M18: 0
A19: 45747.402 | B19: thaine.stefani@gmail.com | C19: Thaine Stefani dos Santos | D19: 034.548.621-83 | E19: 32278 | F19: (67)99682-0430 | G19: Rio Brilhante | H19: Gestão municipal | I19: ass de administração | L19: 45750 | M19: 0
A20: 45748.494 | B20: nunesclaudinei628@gmail.com | C20: Claudinei Nunes | D20: 035.212.591-88 | E20: 33116 | F20: (67)99172-2974 | G20: Eldorado | H20: CACS-FUNDEB | K20: Vice-presidente | L20: 45749 | M20: 0
A21: 45747.426 | B21: semec@taquarussu.ms.gov.br | C21: Amanda Gonsales de Lima | D21: 035.584.901-18 | E21: 34041 | F21: (67)99930-3357 | G21: Taquarussu | H21: Gestão municipal | I21: Auxiliar administrativo | L21: 45750 | M21: 0
A22: 45748.437 | B22: maurosanp_@hotmail.com | C22: Mauro San pereira da Silva | D22: 038.697.801-85 | E22: 34377 | F22: (67)99677-7013 | G22: Iguatemi | H22: Gestão municipal | I22: Gestor transporte | L22: 45749 | M22: 0
A23: 45742.45 | B23: andreluizgomes5691@gmail.com | C23: Andre Luiz Gomes da Silva | D23: 038.713.231-79 | E23: 33394 | F23: (67)98475-4680 | G23: Juti | H23: Gestão municipal | I23: Diretor do Departamento do Transporte Escolar | L23: 45750 | M23: 0
A24: 45742.905 | B24: uesley.u@gmail.com | C24: Uesley Souza | D24: 041.510.051-88 | E24: 33417 | F24: (67)99933-1714 | G24: Rio Brilhante | H24: CACS-FUNDEB | K24: Presidente | L24: 45750 | M24: 0
A25: 45740.667 | B25: anderson-2511@hotmail.com | C25: Anderson Oliveira Souza | D25: 045.727.011-05 | E25: 34298 | F25: (67)98452-5260 | G25: Novo Horizonte do Sul | H25: Gestão municipal | I25: Técnico Administrativo | L25: 45750 | M25: 0
A26: 45733.693 | B26: fagnergalina33@gmail.com | C26: Fagner Rodrigues Galina | D26: 046.804.109-57 | E26: 31113 | F26: (67)99653-5397 | G26: Paranhos | H26: Gestão municipal | I26: Diretor de Transporte Escolar | L26: 45750 | M26: 0
A27: 45747.456 | B27: educacao.matriculadigital@maracaju.ms.gov.br | C27: Gabriel Barbosa Costa | D27: 050.776.421-84 | E27: 34586 | F27: (67)98103-8391 | G27: Maracaju | H27: Gestão municipal | I27: Diretor de Departamento DAS-4 | J27: Sim, sou da nova gestão desse ano em diante | K27: Conselheira | L27: 45750 | M27: 0
A28: 45748.438 | B28: analuizavenite@gmail.com | C28: Ana Luiza Venite Gama | D28: 058.764.141-07 | E28: 36520 | F28: (67)99826-1253 | G28: Rio Brilhante | H28: Gestão municipal | I28: Gestor de núcleo - Convenios e prestação de contas | L28: 45750 | M28: 0
A29: 45741.448 | B29: danimedina826@gmail.com | C29: Sônia Regina Meireles Lago | D29: 063.006.468-74 | E29: 23435 | F29: (67)99923-8890 | G29: Laguna Carapã | H29: CACS-FUNDEB | K29: técnico | L29: 45750 | M29: 0
A30: 45743.135 | B30: luizaquevedonascimento@gmail.com | C30: Luiza Quevedo Nascimento | D30: 065.889.541-90 | E30: 36213 | F30: (67)99938-1694 | G30: Dourados | H30: Gestão municipal | I30: Assistente administrativo | L30: 45749 | M30: 0
A31: 45734.355 | B31: ricartegv@outlook.com.br | C31: Gabriel Vinicius Ricarte Pedrozo | D31: 070.184.021-82 | E31: 36339 | F31: (67)99178-0319 | G31: Maracaju | H31: Gestão municipal | I31: Auxiliar de secretaria do transporte | J31: Mudança de gestão e ingresso de novos servidores | L31: 45750 | M31: 0
A32: 45742.395 | B32: gustavo.texeira33@gmail.com | C32: Gustavo Texeira Silva | D32: 070.308.241-80 | E32: 36763 | F32: (67)99691-2218 | G32: Dourados | H32: Gestão municipal | I32: Responsável pelo transporte Escolar da Prefeitura de Dourados | L32: 45749 | M32: 0
A33: 45740.752 | B33: danimedina826@gmail.com | C33: daniela medina arguelho | D33: 083.222.581-94 | E33: 36569 | F33: (67)99852-3934 | G33: Laguna Carapã | H33: Gestão municipal | I33: técnico | L33: 45750 | M33: 0
A34: 45741.503 | B34: guilhermemateus348@gmail.com | C34: guilherme mateus silva cardoso | D34: 086.228.041-94 | E34: 37837 | F34: (67)99178-8895 | G34: Ponta Porã | H34: Gestão municipal | I34: Assistente no setor de transporte escolar | L34: 45750 | M34: 0
A35: 45747.743 | B35: marcosantoniokol17@gmail.com | C35: Marcos Antônio Kol Rudes | D35: 088.101.191-69 | E35: 52961 | F35: (67)99991-3879 | G35: Aral Moreira | H35: Gestão municipal | I35: Assistente Administrativo | L35: 45749 | M35: 0
A36: 45748.325 | B36: romeugoulart@gmail.com | C36: Romeu Goulart da Silva | D36: 312.097.501-04 | E36: 22943 | F36: (67)98129-2310 | G36: Cassilândia | H36: Gestão municipal | I36: Escriturário Transporte Escolar Municipal | L36: 45750 | M36: 0
A37: 45746.59 | B37: camilosanches2247@hotmail.com | C37: José Camilo Sanches | D37: 312.780.271-49 | E37: 24117 | F37: (67)99698-7171 | G37: Eldorado | H37: Gestão municipal | I37: Diretor de Transporte | L37: 45749 | M37: 0
A38: 45737.543 | B38: profosmar@hotmail.com | C38: Osmar Aparecido Delvecchio | D38: 319.591.219-87 | E38: 21421 | F38: (67)99852-3057 | G38: Amambai | H38: CACS-FUNDEB | K38: Conselheiro | L38: 45749 | M38: 0
A39: 45749.723 | B39: dr.diego.ribeiro25@gmail.com | C39: DIEGO RIBEIRO | D39: 355.073.268-60 | E39: 31913 | F39: (67)99139-1611 | G39: Laguna Carapã | H39: Gestão municipal | I39: TÉCNICO | L39: 45750 | M39: 0
A40: 45734.421 | B40: joaojoao515@gmail.com | C40: João Pereira Alves | D40: 356.418.431-72 | E40: 22821 | F40: (67)99619-8565 | G40: Itaporã | H40: Gestão municipal | I40: Diretor de Departamento deTransporte Escolar | L40: 45749 | M40: 0
...

Sheet Inscritos
A1: XXX | B1: Carimbo de data/hora | C1: Endereço de e-mail | D1: Nome Completo: | E1: CPF | F1: Data de Nascimento | G1: Telefone (XX)XXXXX-XXXX | H1: Município que representa: | I1: Você faz parte do: | J1: Que cargo você ocupa na gestão municipal? | K1: Prezado(a) Gestor(a), Se existe algum caso de sucesso da gestão do transporte escolar no seu município, gostaríamos conhecer mais um pouco ao respeito. Por favor, relate de forma sucinta o caso de sucesso no espaço a seguir: | L1: Que cargo você ocupa no CACS-FUNDEB? | M1: Dia
A2: Antes | B2: 45742.686 | C2: maria_augustha@hotmail.com | D2: Maria Augustha Espíndola Domingues | E2: 000.249.231-84 | F2: 30191 | G2: (67)99971-2118 | H2: Dourados | I2: CACS-FUNDEB | L2: Conselheira representante secretaria municipal de educação de dourados | M2: 45749
A3: Antes | B3: 45744.338 | C3: valdineipavanelli@hotmail.com | D3: valdinei da silva pavanelli | E3: 000.371.471-37 | F3: 30671 | G3: (67)98140-1864 | H3: Japorã | I3: Gestão municipal | J3: chefe de divisão do transporte escolar | M3: 45750
A4: Evento | B4: 45749.406 | C4: geigyson@gmail.com | D4: Geigyson Mendonça Ribeiro | E4: 003.625.511-46 | F4: 30697 | G4: (67)9689-2918 | H4: Caarapó | I4: Gestão municipal | J4: Instrutor de Informática | M4: =+B4 -> 45749.406 | N4: Gestão municipal
A5: Antes | B5: 45748.438 | C5: fv747993@gmail.com | D5: José Fernando Vieira da Silva | E5: 005.338.441-50 | F5: 30850 | G5: (67)99225-2689 | H5: Angélica | I5: Gestão municipal | J5: Chefe de Núcleo de Transporte Escolar | M5: 45749
A6: Antes | B6: 45743.476 | C6: marisantin6@gmail.com | D6: Marilete Santin | E6: 009.602.231-00 | F6: 31173 | G6: (67)99954-7035 | H6: Rio Brilhante | I6: CACS-FUNDEB | L6: Representante Escolas do Campo | M6: 45750
A7: Antes | B7: 45737.488 | C7: semecel@jatei.ms.gov.br | D7: THIAGO RODRIGUES DOS REIS | E7: 012.494.461-20 | F7: 31446 | G7: (67)99848-6764 | H7: Jateí | I7: CACS-FUNDEB | L7: MEMBRO | M7: 45750
A8: Antes | B8: 45748.709 | C8: Transporteescolar@novaalvoradadosul.ms.gov.br | D8: Ozeias Morais da Silva | E8: 014.985.871-00 | F8: 31161 | G8: (67)99678-2795 | H8: Nova Alvorada do Sul | I8: Gestão municipal | J8: Coordenador de transporte escolar | M8: 45750
A9: Evento | B9: 45750.41 | C9: adalbertohonorato@hotmail.com | D9: Adalberto Honorato | E9: 015.174.281-22 | F9: 31509 | G9: (67)99614-9223 | H9: Nova Alvorada do Sul | I9: CACS-FUNDEB | L9: Membro Fundeb | M9: =+B9 -> 45750.41 | N9: CACS-FUNDEB
A10: Antes | B10: 45737.402 | C10: smec2018@outlook.com | D10: Adriana Ramos da Silva | E10: 015.884.291-05 | F10: 31964 | G10: (67)99626-6555 | H10: Batayporã | I10: Gestão municipal | J10: Técnica do Transporte Escolar | M10: 45749
A11: Antes | B11: 45748.479 | C11: tania_ruivo@hotmail.com | D11: Tania Aparecida Ruivo da Luz | E11: 017.339.721-29 | F11: 31923 | G11: (67)99253-6974 | H11: Amambai | I11: Gestão municipal | J11: Secretária de Educação | K11: Não temos ni momento | M11: 45749
A12: Evento | B12: 45749.423 | C12: clariceeducacaof2@gmail.com | D12: Clarice de Almeida Faria | E12: 018.097.781-40 | F12: 31200 | G12: (67)99870-7697 | H12: Paraíso das Águas | I12: Gestão municipal | J12: Chefe da Divisão do transporte escolar | M12: =+B12 -> 45749.423 | N12: Gestão municipal
A13: Antes | B13: 45747.428 | C13: semec@taquarussu.ms.gov.br | D13: Marcio de souza santos | E13: 018.880.441-28 | F13: 31718 | G13: (67)99639-3728 | H13: Taquarussu | I13: Gestão municipal | J13: Diretor do transporte | M13: 45750
A14: Antes | B14: 45748.938 | C14: vanderleifreitas722@gmail.com | D14: Vanderlei de Freitas Santos | E14: 019.226.361-77 | F14: 32384 | G14: (67)99919-6945 | H14: Batayporã | I14: CACS-FUNDEB | L14: Presidente | M14: 45749
A15: Antes | B15: 45748.447 | C15: ricardosm2002@hotmail.com | D15: RICARDO SOUZA MARCHINI | E15: 022.616.841-77 | F15: 37344 | G15: (67)99671-9885 | H15: Angélica | I15: Gestão municipal | J15: CONTADOR | M15: 45749
A16: Evento | B16: 45749.464 | C16: anapedrodugordo12@gmail.com | D16: Ana Cecília Santos Oliveira | E16: 022.800.451-92 | F16: 31610 | G16: (67) 99901-8177 | H16: Douradina | I16: Gestão municipal | J16: Conselheira Tutelar | M16: =+B16 -> 45749.464 | N16: Gestão municipal
A17: Antes | B17: 45733.699 | C17: jaque_hernacki@hotmail.com | D17: Jaqueline Hernacki | E17: 023.145.741-33 | F17: 32243 | G17: (67)99962-9226 | H17: Paranhos | I17: Gestão municipal | J17: Tecnica de prestação de contas | M17: 45750
A18: Antes | B18: 45734.474 | C18: narahbraguini@gmail.com | D18: Nara Henrique Braguini | E18: 023.395.351-58 | F18: 32021 | G18: (67)99971-3774 | H18: Ivinhema | I18: Gestão municipal | J18: Coordenadora | M18: 45749
A19: Evento | B19: 45749.424 | C19: geovaniamachadolemos@gmail.com | D19: Geovania Machado Lemos | E19: 023.432.791-01 | F19: 31512 | G19: (67)99914-3233 | H19: Paraíso das Águas | I19: Gestão municipal | J19: Diretora de apoio administrativo | M19: =+B19 -> 45749.424 | N19: Gestão municipal
A20: Evento | B20: 45749.498 | C20: rafaelfilho.sofia@gmail.com | D20: Rafael Aparecido da Silva Bezerra | E20: 028.916.671-31 | F20: 32475 | G20: (67) 98182-7265 | H20: Bataguassu | I20: Gestão municipal | J20: Coordenador do Transporte Escolar | M20: =+B20 -> 45749.498 | N20: Gestão municipal
A21: Antes | B21: 45747.523 | C21: prof_jcarvalho@outlook.com | D21: Jucimar Carvalho Chaves | E21: 031.051.231-05 | F21: 32514 | G21: (67)99172-4459 | H21: Coronel Sapucaia | I21: CACS-FUNDEB | L21: Técnico | M21: 45749
A22: Antes | B22: 45740.7 | C22: patricnascimentodasilva@gmail.com | D22: Patric Nascimento da Silva | E22: 032.323.241-85 | F22: 32447 | G22: (67)99935-6261 | H22: Maracaju | I22: CACS-FUNDEB | L22: Diretor de transporte | M22: 45750
A23: Antes | B23: 45736.619 | C23: josilaineneves01@gmail.com | D23: JOSILÂINE NEVES DA SILVA | E23: 032.679.841-22 | F23: 32569 | G23: (67)99101-5042 | H23: Caarapó | I23: Gestão municipal | J23: CHEFE DE DEPARTAMENTO DO TRANSPORTE ESCOLAR | M23: 45749
A24: Antes | B24: 45749.706 | C24: simaoschuh1@gmail.com | D24: Simão Sirineu Schuh Dias | E24: 033.593.471-45 | F24: 33019 | G24: (67)99627-7244 | H24: Sete Quedas | I24: CACS-FUNDEB | L24: Representante de pais e alunos | M24: 45750
A25: Antes | B25: 45747.402 | C25: thaine.stefani@gmail.com | D25: Thaine Stefani dos Santos | E25: 034.548.621-83 | F25: 32278 | G25: (67)99682-0430 | H25: Rio Brilhante | I25: Gestão municipal | J25: ass de administração | M25: 45750
A26: Antes | B26: 45748.494 | C26: nunesclaudinei628@gmail.com | D26: Claudinei Nunes | E26: 035.212.591-88 | F26: 33116 | G26: (67)99172-2974 | H26: Eldorado | I26: CACS-FUNDEB | L26: Vice-presidente | M26: 45749
A27: Antes | B27: 45747.426 | C27: semec@taquarussu.ms.gov.br | D27: Amanda Gonsales de Lima | E27: 035.584.901-18 | F27: 34041 | G27: (67)99930-3357 | H27: Taquarussu | I27: Gestão municipal | J27: Auxiliar administrativo | M27: 45750
A28: Antes | B28: 45748.437 | C28: maurosanp_@hotmail.com | D28: Mauro San pereira da Silva | E28: 038.697.801-85 | F28: 34377 | G28: (67)99677-7013 | H28: Iguatemi | I28: Gestão municipal | J28: Gestor transporte | M28: 45749
A29: Antes | B29: 45742.45 | C29: andreluizgomes5691@gmail.com | D29: Andre Luiz Gomes da Silva | E29: 038.713.231-79 | F29: 33394 | G29: (67)98475-4680 | H29: Juti | I29: Gestão municipal | J29: Diretor do Departamento do Transporte Escolar | M29: 45750
A30: Antes | B30: 45742.905 | C30: uesley.u@gmail.com | D30: Uesley Souza | E30: 041.510.051-88 | F30: 33417 | G30: (67)99933-1714 | H30: Rio Brilhante | I30: CACS-FUNDEB | L30: Presidente | M30: 45750
A31: Evento | B31: 45750.544 | C31: julianimalu@gmail.com | D31: Juliani Cristini Sieve | E31: 045.073.871-08 | F31: 34332 | G31: (67)98119-9686 | H31: Novo Horizonte do Sul | I31: CACS-FUNDEB | L31: Represetante de Pais | M31: =+B31 -> 45750.544 | N31: CACS-FUNDEB
A32: Antes | B32: 45740.667 | C32: anderson-2511@hotmail.com | D32: Anderson Oliveira Souza | E32: 045.727.011-05 | F32: 34298 | G32: (67)98452-5260 | H32: Novo Horizonte do Sul | I32: Gestão municipal | J32: Técnico Administrativo | M32: 45750
A33: Antes | B33: 45733.693 | C33: fagnergalina33@gmail.com | D33: Fagner Rodrigues Galina | E33: 046.804.109-57 | F33: 31113 | G33: (67)99653-5397 | H33: Paranhos | I33: Gestão municipal | J33: Diretor de Transporte Escolar | M33: 45750
A34: Evento | B34: 45749.496 | C34: fayane.m@hotmail.com | D34: Fayane Montenegro Gonçalves Paz | E34: 048.862.981-09 | F34: 34577 | G34: (67) 99684-8202 | H34: Douradina | I34: Gestão municipal | J34: Técnica administrativa | M34: =+B34 -> 45749.496 | N34: Gestão municipal
A35: Antes | B35: 45747.456 | C35: educacao.matriculadigital@maracaju.ms.gov.br | D35: Gabriel Barbosa Costa | E35: 050.776.421-84 | F35: 34586 | G35: (67)98103-8391 | H35: Maracaju | I35: Gestão municipal | J35: Diretor de Departamento DAS-4 | K35: Sim, sou da nova gestão desse ano em diante | L35: Conselheira | M35: 45750
A36: Antes | B36: 45748.438 | C36: analuizavenite@gmail.com | D36: Ana Luiza Venite Gama | E36: 058.764.141-07 | F36: 36520 | G36: (67)99826-1253 | H36: Rio Brilhante | I36: Gestão municipal | J36: Gestor de núcleo - Convenios e prestação de contas | M36: 45750
A37: Antes | B37: 45741.448 | C37: danimedina826@gmail.com | D37: Sônia Regina Meireles Lago | E37: 063.006.468-74 | F37: 23435 | G37: (67)99923-8890 | H37: Laguna Carapã | I37: CACS-FUNDEB | L37: técnico | M37: 45750
A38: Antes | B38: 45743.135 | C38: luizaquevedonascimento@gmail.com | D38: Luiza Quevedo Nascimento | E38: 065.889.541-90 | F38: 36213 | G38: (67)99938-1694 | H38: Dourados | I38: Gestão municipal | J38: Assistente administrativo | M38: 45749
A39: Antes | B39: 45734.355 | C39: ricartegv@outlook.com.br | D39: Gabriel Vinicius Ricarte Pedrozo | E39: 070.184.021-82 | F39: 36339 | G39: (67)99178-0319 | H39: Maracaju | I39: Gestão municipal | J39: Auxiliar de secretaria do transporte | K39: Mudança de gestão e ingresso de novos servidores | M39: 45750
A40: Antes | B40: 45742.395 | C40: gustavo.texeira33@gmail.com | D40: Gustavo Texeira Silva | E40: 070.308.241-80 | F40: 36763 | G40: (67)99691-2218 | H40: Dourados | I40: Gestão municipal | J40: Responsável pelo transporte Escolar da Prefeitura de Dourados | M40: 45749
...

Sheet Resumo 
G1: CACS-FUNDEB | H1: Gestão municipal | I1: TOTAL | J1: CACS-FUNDEB | K1: Gestão municipal | L1: TOTAL
N2: =COUNTIF(J5:J41,0) -> 16 | O2: =COUNTIF(K5:K41,0) -> 3 | P2: =COUNTIF(L5:L41,0) -> 2
C3: Data | D3: Código IBGE | E3: Município | F3: Distância (km) | G3: Presentes | J3: Inscritos | N3: =37-N2 -> 21 | O3: =37-O2 -> 34 | P3: =37-P2 -> 35
G4: CACS | H4: GESTOR | I4: TOTAL | J4: CACS | K4: GESTOR | L4: TOTAL
B5: 1 | C5: 45749 | D5: 5000609 | E5: Amambai | F5: 109 | G5: =COUNTIFS(Presentes!$H$2:$H$93,'Resumo '!G$1,Presentes!$G$2:$G$93,'Resumo '!$E5) -> 3 | H5: =COUNTIFS(Presentes!$H$2:$H$93,'Resumo '!H$1,Presentes!$G$2:$G$93,'Resumo '!$E5) -> 1 | I5: =+G5+H5 -> 4 | J5: =COUNTIFS(Inscritos!$I$2:$I$110,'Resumo '!J$1,Inscritos!$H$2:$H$110,'Resumo '!$E5) -> 3 | K5: =COUNTIFS(Inscritos!$I$2:$I$110,'Resumo '!K$1,Inscritos!$H$2:$H$110,'Resumo '!$E5) -> 3 | L5: =+J5+K5 -> 6 | M5: =IF(AND(J5>0,K5=0),1,0) -> 0 | N5: =+_xlfn.CONCAT(G5,"/",J5) -> 3/3 | O5: =+_xlfn.CONCAT(H5,"/",K5) -> 1/3 | P5: =+_xlfn.CONCAT(I5,"/",L5) -> 4/6
B6: 2 | C6: 45749 | D6: 5000807 | E6: Anaurilândia | F6: 245 | G6: =COUNTIFS(Presentes!$H$2:$H$93,'Resumo '!G$1,Presentes!$G$2:$G$93,'Resumo '!$E6) -> 0 | H6: =COUNTIFS(Presentes!$H$2:$H$93,'Resumo '!H$1,Presentes!$G$2:$G$93,'Resumo '!$E6) -> 2 | I6: =+G6+H6 -> 2 | J6: =COUNTIFS(Inscritos!$I$2:$I$110,'Resumo '!J$1,Inscritos!$H$2:$H$110,'Resumo '!$E6) -> 0 | K6: =COUNTIFS(Inscritos!$I$2:$I$110,'Resumo '!K$1,Inscritos!$H$2:$H$110,'Resumo '!$E6) -> 2 | L6: =+J6+K6 -> 2 | M6: =IF(AND(J6>0,K6=0),1,0) -> 0 | N6: =+_xlfn.CONCAT(G6,"/",J6) -> 0/0 | O6: =+_xlfn.CONCAT(H6,"/",K6) -> 2/2 | P6: =+_xlfn.CONCAT(I6,"/",L6) -> 2/2
B7: 3 | C7: 45749 | D7: 5000856 | E7: Angélica | F7: 136 | G7: =COUNTIFS(Presentes!$H$2:$H$93,'Resumo '!G$1,Presentes!$G$2:$G$93,'Resumo '!$E7) -> 0 | H7: =COUNTIFS(Presentes!$H$2:$H$93,'Resumo '!H$1,Presentes!$G$2:$G$93,'Resumo '!$E7) -> 2 | I7: =+G7+H7 -> 2 | J7: =COUNTIFS(Inscritos!$I$2:$I$110,'Resumo '!J$1,Inscritos!$H$2:$H$110,'Resumo '!$E7) -> 0 | K7: =COUNTIFS(Inscritos!$I$2:$I$110,'Resumo '!K$1,Inscritos!$H$2:$H$110,'Resumo '!$E7) -> 2 | L7: =+J7+K7 -> 2 | M7: =IF(AND(J7>0,K7=0),1,0) -> 0 | N7: =+_xlfn.CONCAT(G7,"/",J7) -> 0/0 | O7: =+_xlfn.CONCAT(H7,"/",K7) -> 2/2 | P7: =+_xlfn.CONCAT(I7,"/",L7) -> 2/2
B8: 4 | C8: 45749 | D8: 5001243 | E8: Aral Moreira | F8: 149 | G8: =COUNTIFS(Presentes!$H$2:$H$93,'Resumo '!G$1,Presentes!$G$2:$G$93,'Resumo '!$E8) -> 0 | H8: =COUNTIFS(Presentes!$H$2:$H$93,'Resumo '!H$1,Presentes!$G$2:$G$93,'Resumo '!$E8) -> 2 | I8: =+G8+H8 -> 2 | J8: =COUNTIFS(Inscritos!$I$2:$I$110,'Resumo '!J$1,Inscritos!$H$2:$H$110,'Resumo '!$E8) -> 0 | K8: =COUNTIFS(Inscritos!$I$2:$I$110,'Resumo '!K$1,Inscritos!$H$2:$H$110,'Resumo '!$E8) -> 2 | L8: =+J8+K8 -> 2 | M8: =IF(AND(J8>0,K8=0),1,0) -> 0 | N8: =+_xlfn.CONCAT(G8,"/",J8) -> 0/0 | O8: =+_xlfn.CONCAT(H8,"/",K8) -> 2/2 | P8: =+_xlfn.CONCAT(I8,"/",L8) -> 2/2
B9: 5 | C9: 45749 | D9: 5001904 | E9: Bataguassu | F9: 328 | G9: =COUNTIFS(Presentes!$H$2:$H$93,'Resumo '!G$1,Presentes!$G$2:$G$93,'Resumo '!$E9) -> 0 | H9: =COUNTIFS(Presentes!$H$2:$H$93,'Resumo '!H$1,Presentes!$G$2:$G$93,'Resumo '!$E9) -> 2 | I9: =+G9+H9 -> 2 | J9: =COUNTIFS(Inscritos!$I$2:$I$110,'Resumo '!J$1,Inscritos!$H$2:$H$110,'Resumo '!$E9) -> 0 | K9: =COUNTIFS(Inscritos!$I$2:$I$110,'Resumo '!K$1,Inscritos!$H$2:$H$110,'Resumo '!$E9) -> 2 | L9: =+J9+K9 -> 2 | M9: =IF(AND(J9>0,K9=0),1,0) -> 0 | N9: =+_xlfn.CONCAT(G9,"/",J9) -> 0/0 | O9: =+_xlfn.CONCAT(H9,"/",K9) -> 2/2 | P9: =+_xlfn.CONCAT(I9,"/",L9) -> 2/2
B10: 6 | C10: 45749 | D10: 5002001 | E10: Batayporã | F10: 180 | G10: =COUNTIFS(Presentes!$H$2:$H$93,'Resumo '!G$1,Presentes!$G$2:$G$93,'Resumo '!$E10) -> 2 | H10: =COUNTIFS(Presentes!$H$2:$H$93,'Resumo '!H$1,Presentes!$G$2:$G$93,'Resumo '!$E10) -> 2 | I10: =+G10+H10 -> 4 | J10: =COUNTIFS(Inscritos!$I$2:$I$110,'Resumo '!J$1,Inscritos!$H$2:$H$110,'Resumo '!$E10) -> 2 | K10: =COUNTIFS(Inscritos!$I$2:$I$110,'Resumo '!K$1,Inscritos!$H$2:$H$110,'Resumo '!$E10) -> 2 | L10: =+J10+K10 -> 4 | M10: =IF(AND(J10>0,K10=0),1,0) -> 0 | N10: =+_xlfn.CONCAT(G10,"/",J10) -> 2/2 | O10: =+_xlfn.CONCAT(H10,"/",K10) -> 2/2 | P10: =+_xlfn.CONCAT(I10,"/",L10) -> 4/4
B11: 7 | C11: 45749 | D11: 5002407 | E11: Caarapó | F11: 52 | G11: =COUNTIFS(Presentes!$H$2:$H$93,'Resumo '!G$1,Presentes!$G$2:$G$93,'Resumo '!$E11) -> 1 | H11: =COUNTIFS(Presentes!$H$2:$H$93,'Resumo '!H$1,Presentes!$G$2:$G$93,'Resumo '!$E11) -> 3 | I11: =+G11+H11 -> 4 | J11: =COUNTIFS(Inscritos!$I$2:$I$110,'Resumo '!J$1,Inscritos!$H$2:$H$110,'Resumo '!$E11) -> 1 | K11: =COUNTIFS(Inscritos!$I$2:$I$110,'Resumo '!K$1,Inscritos!$H$2:$H$110,'Resumo '!$E11) -> 3 | L11: =+J11+K11 -> 4 | M11: =IF(AND(J11>0,K11=0),1,0) -> 0 | N11: =+_xlfn.CONCAT(G11,"/",J11) -> 1/1 | O11: =+_xlfn.CONCAT(H11,"/",K11) -> 3/3 | P11: =+_xlfn.CONCAT(I11,"/",L11) -> 4/4
B12: 8 | C12: 45749 | D12: 5003157 | E12: Coronel Sapucaia | F12: 174 | G12: =COUNTIFS(Presentes!$H$2:$H$93,'Resumo '!G$1,Presentes!$G$2:$G$93,'Resumo '!$E12) -> 1 | H12: =COUNTIFS(Presentes!$H$2:$H$93,'Resumo '!H$1,Presentes!$G$2:$G$93,'Resumo '!$E12) -> 1 | I12: =+G12+H12 -> 2 | J12: =COUNTIFS(Inscritos!$I$2:$I$110,'Resumo '!J$1,Inscritos!$H$2:$H$110,'Resumo '!$E12) -> 1 | K12: =COUNTIFS(Inscritos!$I$2:$I$110,'Resumo '!K$1,Inscritos!$H$2:$H$110,'Resumo '!$E12) -> 2 | L12: =+J12+K12 -> 3 | M12: =IF(AND(J12>0,K12=0),1,0) -> 0 | N12: =+_xlfn.CONCAT(G12,"/",J12) -> 1/1 | O12: =+_xlfn.CONCAT(H12,"/",K12) -> 1/2 | P12: =+_xlfn.CONCAT(I12,"/",L12) -> 2/3
B13: 9 | C13: 45749 | D13: 5003454 | E13: Deodápolis | F13: 79 | G13: =COUNTIFS(Presentes!$H$2:$H$93,'Resumo '!G$1,Presentes!$G$2:$G$93,'Resumo '!$E13) -> 0 | H13: =COUNTIFS(Presentes!$H$2:$H$93,'Resumo '!H$1,Presentes!$G$2:$G$93,'Resumo '!$E13) -> 1 | I13: =+G13+H13 -> 1 | J13: =COUNTIFS(Inscritos!$I$2:$I$110,'Resumo '!J$1,Inscritos!$H$2:$H$110,'Resumo '!$E13) -> 0 | K13: =COUNTIFS(Inscritos!$I$2:$I$110,'Resumo '!K$1,Inscritos!$H$2:$H$110,'Resumo '!$E13) -> 1 | L13: =+J13+K13 -> 1 | M13: =IF(AND(J13>0,K13=0),1,0) -> 0 | N13: =+_xlfn.CONCAT(G13,"/",J13) -> 0/0 | O13: =+_xlfn.CONCAT(H13,"/",K13) -> 1/1 | P13: =+_xlfn.CONCAT(I13,"/",L13) -> 1/1
B14: 10 | C14: 45749 | D14: 5003504 | E14: Douradina | F14: 38 | G14: =COUNTIFS(Presentes!$H$2:$H$93,'Resumo '!G$1,Presentes!$G$2:$G$93,'Resumo '!$E14) -> 0 | H14: =COUNTIFS(Presentes!$H$2:$H$93,'Resumo '!H$1,Presentes!$G$2:$G$93,'Resumo '!$E14) -> 3 | I14: =+G14+H14 -> 3 | J14: =COUNTIFS(Inscritos!$I$2:$I$110,'Resumo '!J$1,Inscritos!$H$2:$H$110,'Resumo '!$E14) -> 0 | K14: =COUNTIFS(Inscritos!$I$2:$I$110,'Resumo '!K$1,Inscritos!$H$2:$H$110,'Resumo '!$E14) -> 3 | L14: =+J14+K14 -> 3 | M14: =IF(AND(J14>0,K14=0),1,0) -> 0 | N14: =+_xlfn.CONCAT(G14,"/",J14) -> 0/0 | O14: =+_xlfn.CONCAT(H14,"/",K14) -> 3/3 | P14: =+_xlfn.CONCAT(I14,"/",L14) -> 3/3
B15: 11 | C15: 45749 | D15: 5003702 | E15: Dourados | F15: 0 | G15: =COUNTIFS(Presentes!$H$2:$H$93,'Resumo '!G$1,Presentes!$G$2:$G$93,'Resumo '!$E15) -> 2 | H15: =COUNTIFS(Presentes!$H$2:$H$93,'Resumo '!H$1,Presentes!$G$2:$G$93,'Resumo '!$E15) -> 3 | I15: =+G15+H15 -> 5 | J15: =COUNTIFS(Inscritos!$I$2:$I$110,'Resumo '!J$1,Inscritos!$H$2:$H$110,'Resumo '!$E15) -> 2 | K15: =COUNTIFS(Inscritos!$I$2:$I$110,'Resumo '!K$1,Inscritos!$H$2:$H$110,'Resumo '!$E15) -> 3 | L15: =+J15+K15 -> 5 | M15: =IF(AND(J15>0,K15=0),1,0) -> 0 | N15: =+_xlfn.CONCAT(G15,"/",J15) -> 2/2 | O15: =+_xlfn.CONCAT(H15,"/",K15) -> 3/3 | P15: =+_xlfn.CONCAT(I15,"/",L15) -> 5/5
B16: 12 | C16: 45749 | D16: 5003751 | E16: Eldorado | F16: 115 | G16: =COUNTIFS(Presentes!$H$2:$H$93,'Resumo '!G$1,Presentes!$G$2:$G$93,'Resumo '!$E16) -> 1 | H16: =COUNTIFS(Presentes!$H$2:$H$93,'Resumo '!H$1,Presentes!$G$2:$G$93,'Resumo '!$E16) -> 1 | I16: =+G16+H16 -> 2 | J16: =COUNTIFS(Inscritos!$I$2:$I$110,'Resumo '!J$1,Inscritos!$H$2:$H$110,'Resumo '!$E16) -> 1 | K16: =COUNTIFS(Inscritos!$I$2:$I$110,'Resumo '!K$1,Inscritos!$H$2:$H$110,'Resumo '!$E16) -> 1 | L16: =+J16+K16 -> 2 | M16: =IF(AND(J16>0,K16=0),1,0) -> 0 | N16: =+_xlfn.CONCAT(G16,"/",J16) -> 1/1 | O16: =+_xlfn.CONCAT(H16,"/",K16) -> 1/1 | P16: =+_xlfn.CONCAT(I16,"/",L16) -> 2/2
... B39: 35 | C39: 45750 | D39: 5008404 | E39: Vicentina | F39: 50 | G39: =COUNTIFS(Presentes!$H$2:$H$93,'Resumo '!G$1,Presentes!$G$2:$G$93,'Resumo '!$E39) -> 1 | H39: =COUNTIFS(Presentes!$H$2:$H$93,'Resumo '!H$1,Presentes!$G$2:$G$93,'Resumo '!$E39) -> 0 | I39: =+G39+H39 -> 1 | J39: =COUNTIFS(Inscritos!$I$2:$I$110,'Resumo '!J$1,Inscritos!$H$2:$H$110,'Resumo '!$E39) -> 1 | K39: =COUNTIFS(Inscritos!$I$2:$I$110,'Resumo '!K$1,Inscritos!$H$2:$H$110,'Resumo '!$E39) -> 0 | L39: =+J39+K39 -> 1 | M39: =IF(AND(J39>0,K39=0),1,0) -> 1 | N39: =+_xlfn.CONCAT(G39,"/",J39) -> 1/1 | O39: =+_xlfn.CONCAT(H39,"/",K39) -> 0/0 | P39: =+_xlfn.CONCAT(I39,"/",L39) -> 1/1
B40: 36 | C40: 45749 | E40: Paraíso das Águas | G40: =COUNTIFS(Presentes!$H$2:$H$93,'Resumo '!G$1,Presentes!$G$2:$G$93,'Resumo '!$E40) -> 0 | H40: =COUNTIFS(Presentes!$H$2:$H$93,'Resumo '!H$1,Presentes!$G$2:$G$93,'Resumo '!$E40) -> 3 | I40: =+G40+H40 -> 3 | J40: =COUNTIFS(Inscritos!$I$2:$I$110,'Resumo '!J$1,Inscritos!$H$2:$H$110,'Resumo '!$E40) -> 0 | K40: =COUNTIFS(Inscritos!$I$2:$I$110,'Resumo '!K$1,Inscritos!$H$2:$H$110,'Resumo '!$E40) -> 3 | L40: =+J40+K40 -> 3 | M40: =IF(AND(J40>0,K40=0),1,0) -> 0 | N40: =+_xlfn.CONCAT(G40,"/",J40) -> 0/0 | O40: =+_xlfn.CONCAT(H40,"/",K40) -> 3/3 | P40: =+_xlfn.CONCAT(I40,"/",L40) -> 3/3
B41: 37 | C41: 45750 | E41: Cassilândia | G41: =COUNTIFS(Presentes!$H$2:$H$93,'Resumo '!G$1,Presentes!$G$2:$G$93,'Resumo '!$E41) -> 0 | H41: =COUNTIFS(Presentes!$H$2:$H$93,'Resumo '!H$1,Presentes!$G$2:$G$93,'Resumo '!$E41) -> 2 | I41: =+G41+H41 -> 2 | J41: =COUNTIFS(Inscritos!$I$2:$I$110,'Resumo '!J$1,Inscritos!$H$2:$H$110,'Resumo '!$E41) -> 0 | K41: =COUNTIFS(Inscritos!$I$2:$I$110,'Resumo '!K$1,Inscritos!$H$2:$H$110,'Resumo '!$E41) -> 2 | L41: =+J41+K41 -> 2 | M41: =IF(AND(J41>0,K41=0),1,0) -> 0 | N41: =+_xlfn.CONCAT(G41,"/",J41) -> 0/0 | O41: =+_xlfn.CONCAT(H41,"/",K41) -> 2/2 | P41: =+_xlfn.CONCAT(I41,"/",L41) -> 2/2
C42: Pessoas Inscritas | G42: =SUM(G5:G41) -> 32 | H42: =SUM(H5:H41) -> 60 | I42: =SUM(I5:I41) -> 92 | J42: =SUM(J5:J41) -> 37 | K42: =SUM(K5:K41) -> 72 | L42: =SUM(L5:L41) -> 109 | N42: =+_xlfn.CONCAT(G42,"/",J42) -> 32/37 | O42: =+_xlfn.CONCAT(H42,"/",K42) -> 60/72 | P42: =+_xlfn.CONCAT(I42,"/",L42) -> 92/109 | Q42: =92/109 -> 0.8440367
C43: Municípios com pelo menos um representante inscrito | G43: =COUNTIF(G5:G41,"<>0") -> 20 | H43: =COUNTIF(H5:H41,"<>0") -> 34 | I43: =COUNTIF(I5:I41,"<>0") -> 35 | J43: =COUNTIF(J5:J41,"<>0") -> 21 | K43: =COUNTIF(K5:K41,"<>0") -> 34 | L43: =COUNTIF(L5:L41,"<>0") -> 35 | N43: =+_xlfn.CONCAT(G43,"/",J43) -> 20/21 | O43: =+_xlfn.CONCAT(H43,"/",K43) -> 34/34 | P43: =+_xlfn.CONCAT(I43,"/",L43) -> 35/35
N44: CACS | O44: GESTOR | P44: TOTAL
Q45: =32/37 -> 0.86486486
Q46: =60/72 -> 0.83333333
